Workbook

Sheet spmv_1
A1: Matrix | B1: Rank | D1: Local NNZ | E1: GFLOPS | G1: Iter_0 | H1: Iter_1 | I1: Iter_2 | J1: Iter_3 | K1: Iter_4 | L1: Iter_5 | M1: Iter_6 | N1: Iter_7 | O1: Iter_8 | P1: Iter_9 | R1: 90 percentile
A2: bmwcra_1.mtx | B2: 0 | D2: 10644002 | E2: 1.255874 | G2: 0.017351389 | H2: 0.016767263 | I2: 0.018069983 | J2: 0.017008781 | K2: 0.016972303 | L2: 0.01730299 | M2: 0.016360044 | N2: 0.015614986 | O2: 0.016727448 | P2: 0.017332315 | R2: =PERCENTILE(G2:P2,0.9) -> 0.017423248
A5: Matrix | B5: Rank | D5: Local NNZ | E5: GFLOPS | G5: Iter_0 | H5: Iter_1 | I5: Iter_2 | J5: Iter_3 | K5: Iter_4 | L5: Iter_5 | M5: Iter_6 | N5: Iter_7 | O5: Iter_8 | P5: Iter_9 | R5: 90 percentile
A6: ML_Geer.mtx | B6: 0 | D6: 110879972 | E6: 1.356499 | G6: 0.16126299 | H6: 0.16874123 | I6: 0.16817832 | J6: 0.15973425 | K6: 0.16493392 | L6: 0.1623981 | M6: 0.16206217 | N6: 0.16077113 | O6: 0.16149044 | P6: 0.16522336 | R6: =PERCENTILE(G6:P6,0.9) -> 0.16823461
A9: Matrix | B9: Rank | D9: Local NNZ | E9: GFLOPS | G9: Iter_0 | H9: Iter_1 | I9: Iter_2 | J9: Iter_3 | K9: Iter_4 | L9: Iter_5 | M9: Iter_6 | N9: Iter_7 | O9: Iter_8 | P9: Iter_9 | R9: 90 percentile
A10: msdoor.mtx | B10: 0 | D10: 20240935 | E10: 1.182623 | G10: 0.035825014 | H10: 0.034771681 | I10: 0.034943581 | J10: 0.034598827 | K10: 0.034837723 | L10: 0.034459352 | M10: 0.032521486 | N10: 0.033790827 | O10: 0.033330441 | P10: 0.033226967 | R10: =PERCENTILE(G10:P10,0.9) -> 0.035031724
A13: Matrix | B13: Rank | D13: Local NNZ | E13: GFLOPS | G13: Iter_0 | H13: Iter_1 | I13: Iter_2 | J13: Iter_3 | K13: Iter_4 | L13: Iter_5 | M13: Iter_6 | N13: Iter_7 | O13: Iter_8 | P13: Iter_9 | R13: 90 percentile
A14: nlpkkt240.mtx | B14: 0 | D14: 774472352 | E14: 1.457491 | G14: 1.0222895 | H14: 1.0357954 | I14: 1.1124063 | J14: 1.0311396 | K14: 1.096113 | L14: 1.0902107 | M14: 1.0319834 | N14: 1.1036706 | O14: 1.0191967 | P14: 1.0846672 | R14: =PERCENTILE(G14:P14,0.9) -> 1.1045442
A17: Matrix | B17: Rank | D17: Local NNZ | E17: GFLOPS | G17: Iter_0 | H17: Iter_1 | I17: Iter_2 | J17: Iter_3 | K17: Iter_4 | L17: Iter_5 | M17: Iter_6 | N17: Iter_7 | O17: Iter_8 | P17: Iter_9 | R17: 90 percentile
A18: Pflow_742.mtx | B18: 0 | D18: 37138461 | E18: 1.265726 | G18: 0.058051348 | H18: 0.086965084 | I18: 0.076491356 | J18: 0.061322689 | K18: 0.056359768 | L18: 0.053620815 | M18: 0.048618078 | N18: 0.048573017 | O18: 0.04839015 | P18: 0.048440456 | R18: =PERCENTILE(G18:P18,0.9) -> 0.077538729

Sheet spmv_2
A1: Matrix | B1: Rank | D1: Local NNZ | E1: GFLOPS | G1: Iter_0 | H1: Iter_1 | I1: Iter_2 | J1: Iter_3 | K1: Iter_4 | L1: Iter_5 | M1: Iter_6 | N1: Iter_7 | O1: Iter_8 | P1: Iter_9 | R1: 90 percentile | S1: Speedup | T1: Efficiency
A2: bmwcra_1.mtx | B2: 0 | D2: 5317852 | E2: 1.376476 | G2: 0.007612467 | H2: 0.007595778 | I2: 0.008028984 | J2: 0.007710934 | K2: 0.007650137 | L2: 0.007810831 | M2: 0.007652283 | N2: 0.007688284 | O2: 0.007738113 | P2: 0.007779837 | R2: =PERCENTILE(G2:P2,0.9) -> 0.0078326463 | S2: =spmv_1!R$2/R2 -> 2.2244396 | T2: =S2/2 -> 1.1122198
A3: bmwcra_1.mtx | B3: 1 | D3: 5326150 | E3: 1.382668 | G3: 0.007544756 | H3: 0.00762248 | I3: 0.007998943 | J3: 0.007754564 | K3: 0.007649183 | L3: 0.007591009 | M3: 0.007543802 | N3: 0.007698298 | O3: 0.007809401 | P3: 0.007829189 | R3: =PERCENTILE(G3:P3,0.9) -> 0.0078461644 | S3: =spmv_1!R$2/R3 -> 2.2206071 | T3: =S3/2 -> 1.1103036
A6: Matrix | B6: Rank | D6: Local NNZ | E6: GFLOPS | G6: Iter_0 | H6: Iter_1 | I6: Iter_2 | J6: Iter_3 | K6: Iter_4 | L6: Iter_5 | M6: Iter_6 | N6: Iter_7 | O6: Iter_8 | P6: Iter_9 | R6: 90 percentile | S6: Speedup | T6: Efficiency
A7: ML_Geer.mtx | B7: 0 | D7: 55439986 | E7: 1.454966 | G7: 0.075138807 | H7: 0.07688117 | I7: 0.076182842 | J7: 0.076216221 | K7: 0.076472521 | L7: 0.077010632 | M7: 0.075824976 | N7: 0.075845957 | O7: 0.076472282 | P7: 0.076034307 | R7: =PERCENTILE(G7:P7,0.9) -> 0.076894116 | S7: =spmv_1!R$6/R7 -> 2.1878736 | T7: =S7/2 -> 1.0939368
A8: ML_Geer.mtx | B8: 1 | D8: 55439986 | E8: 1.444998 | G8: 0.075662613 | H8: 0.076557636 | I8: 0.077471972 | J8: 0.076376677 | K8: 0.077279329 | L8: 0.076523781 | M8: 0.077392101 | N8: 0.076412678 | O8: 0.077500105 | P8: 0.076159716 | R8: =PERCENTILE(G8:P8,0.9) -> 0.077474785 | S8: =spmv_1!R$6/R8 -> 2.1714757 | T8: =S8/2 -> 1.0857378
A11: Matrix | B11: Rank | D11: Local NNZ | E11: GFLOPS | G11: Iter_0 | H11: Iter_1 | I11: Iter_2 | J11: Iter_3 | K11: Iter_4 | L11: Iter_5 | M11: Iter_6 | N11: Iter_7 | O11: Iter_8 | P11: Iter_9 | R11: 90 percentile | S11: Speedup | T11: Efficiency
A12: msdoor.mtx | B12: 0 | D12: 10114572 | E12: 1.257795 | G12: 0.016113758 | H12: 0.015937805 | I12: 0.016327858 | J12: 0.016388178 | K12: 0.015745878 | L12: 0.015846252 | M12: 0.016442299 | N12: 0.016054153 | O12: 0.015816927 | P12: 0.01615715 | R12: =PERCENTILE(G12:P12,0.9) -> 0.01639359 | S12: =spmv_1!R$10/R12 -> 2.136916 | T12: =S12/2 -> 1.068458
A13: msdoor.mtx | B13: 1 | D13: 10126363 | E13: 1.24242 | G13: 0.016155243 | H13: 0.016073942 | I13: 0.016501904 | J13: 0.01659584 | K13: 0.016120911 | L13: 0.016175032 | M13: 0.016672134 | N13: 0.016250372 | O13: 0.016085386 | P13: 0.016379595 | R13: =PERCENTILE(G13:P13,0.9) -> 0.016603469 | S13: =spmv_1!R$10/R13 -> 2.1099039 | T13: =S13/2 -> 1.0549519
A16: Matrix | B16: Rank | D16: Local NNZ | E16: GFLOPS | G16: Iter_0 | H16: Iter_1 | I16: Iter_2 | J16: Iter_3 | K16: Iter_4 | L16: Iter_5 | M16: Iter_6 | N16: Iter_7 | O16: Iter_8 | P16: Iter_9 | R16: 90 percentile | S16: Speedup | T16: Efficiency
A17: nlpkkt240.mtx | B17: 0 | D17: 387236176 | E17: 1.296204 | G17: 0.59795189 | H17: 0.59888363 | I17: 0.59745836 | J17: 0.5950191 | K17: 0.59725761 | L17: 0.59786606 | M17: 0.5986793 | N17: 0.59662843 | O17: 0.59825754 | P17: 0.59692383 | R17: =PERCENTILE(G17:P17,0.9) -> 0.59869974 | S17: =spmv_1!R$14/R17 -> 1.844905 | T17: =S17/2 -> 0.92245252
A18: nlpkkt240.mtx | B18: 1 | D18: 387236176 | E18: 1.333328 | G18: 0.58260798 | H18: 0.58316445 | I18: 0.58440351 | J18: 0.57431698 | K18: 0.57843995 | L18: 0.5831604 | M18: 0.5822649 | N18: 0.57984829 | O18: 0.58020019 | P18: 0.58015871 | R18: =PERCENTILE(G18:P18,0.9) -> 0.58328836 | S18: =spmv_1!R$14/R18 -> 1.8936503 | T18: =S18/2 -> 0.94682514
A21: Matrix | B21: Rank | D21: Local NNZ | E21: GFLOPS | G21: Iter_0 | H21: Iter_1 | I21: Iter_2 | J21: Iter_3 | K21: Iter_4 | L21: Iter_5 | M21: Iter_6 | N21: Iter_7 | O21: Iter_8 | P21: Iter_9 | R21: 90 percentile | S21: Speedup | T21: Efficiency
A22: Pflow_742.mtx | B22: 0 | D22: 18440207 | E22: 1.39035 | G22: 0.025316954 | H22: 0.026937723 | I22: 0.02730298 | J22: 0.027282238 | K22: 0.027074575 | L22: 0.026521683 | M22: 0.026664019 | N22: 0.025829077 | O22: 0.026721954 | P22: 0.025608778 | R22: =PERCENTILE(G22:P22,0.9) -> 0.027284312 | S22: =spmv_1!R$18/R22 -> 2.8418795 | T22: =S22/2 -> 1.4209398
A23: Pflow_742.mtx | B23: 1 | D23: 18698254 | E23: 1.352792 | G23: 0.026980639 | H23: 0.028142214 | I23: 0.028184652 | J23: 0.027744532 | K23: 0.027686119 | L23: 0.0275805 | M23: 0.027682781 | N23: 0.027152777 | O23: 0.028059959 | P23: 0.027225256 | R23: =PERCENTILE(G23:P23,0.9) -> 0.028146458 | S23: =spmv_1!R$18/R23 -> 2.7548308 | T23: =S23/2 -> 1.3774154

Sheet spmv_4
A1: Matrix | B1: Rank | D1: Local NNZ | E1: GFLOPS | G1: Iter_0 | H1: Iter_1 | I1: Iter_2 | J1: Iter_3 | K1: Iter_4 | L1: Iter_5 | M1: Iter_6 | N1: Iter_7 | O1: Iter_8 | P1: Iter_9 | R1: 90 percentile | S1: Speedup | T1: Efficiency
A2: bmwcra_1.mtx | B2: 0 | D2: 2658799 | E2: 1.445602 | G2: 0.003935099 | H2: 0.003746748 | I2: 0.00366497 | J2: 0.00366044 | K2: 0.00370574 | L2: 0.003673792 | M2: 0.003610134 | N2: 0.003634453 | O2: 0.003614664 | P2: 0.003538609 | R2: =PERCENTILE(G2:P2,0.9) -> 0.0037655831 | S2: =spmv_1!R$2/R2 -> 4.6269722 | T2: =S2/4 -> 1.1567431
A3: bmwcra_1.mtx | B3: 1 | D3: 2663504 | E3: 1.391191 | G3: 0.004188538 | H3: 0.004042864 | I3: 0.003933668 | J3: 0.003793716 | K3: 0.003788471 | L3: 0.003760815 | M3: 0.003698587 | N3: 0.003730536 | O3: 0.00373292 | P3: 0.003620863 | R3: =PERCENTILE(G3:P3,0.9) -> 0.0040574314 | S3: =spmv_1!R$2/R3 -> 4.2941572 | T3: =S3/4 -> 1.0735393
A4: bmwcra_1.mtx | B4: 2 | D4: 2659053 | E4: 1.374209 | G4: 0.004246235 | H4: 0.004076719 | I4: 0.003950596 | J4: 0.003813505 | K4: 0.003824234 | L4: 0.003799677 | M4: 0.003753901 | N4: 0.003787041 | O4: 0.003770828 | P4: 0.003676653 | R4: =PERCENTILE(G4:P4,0.9) -> 0.0040936706 | S4: =spmv_1!R$2/R4 -> 4.2561432 | T4: =S4/4 -> 1.0640358
A5: bmwcra_1.mtx | B5: 3 | D5: 2662646 | E5: 1.420226 | G5: 0.004158497 | H5: 0.003963232 | I5: 0.003861189 | J5: 0.003712177 | K5: 0.003690481 | L5: 0.003674746 | M5: 0.0036273 | N5: 0.003640175 | O5: 0.003621101 | P5: 0.003547192 | R5: =PERCENTILE(G5:P5,0.9) -> 0.0039827585 | S5: =spmv_1!R$2/R5 -> 4.3746686 | T5: =S5/4 -> 1.0936671
A8: Matrix | B8: Rank | D8: Local NNZ | E8: GFLOPS | G8: Iter_0 | H8: Iter_1 | I8: Iter_2 | J8: Iter_3 | K8: Iter_4 | L8: Iter_5 | M8: Iter_6 | N8: Iter_7 | O8: Iter_8 | P8: Iter_9 | R8: 90 percentile | S8: Speedup | T8: Efficiency
A9: ML_Geer.mtx | B9: 0 | D9: 27720658 | E9: 1.351714 | G9: 0.039351702 | H9: 0.041552544 | I9: 0.041501522 | J9: 0.040318966 | K9: 0.041270494 | L9: 0.041276693 | M9: 0.04093504 | N9: 0.041595936 | O9: 0.040893793 | P9: 0.041459084 | R9: =PERCENTILE(G9:P9,0.9) -> 0.041556883 | S9: =spmv_1!R$6/R9 -> 4.0482971 | T9: =S9/4 -> 1.0120743
A10: ML_Geer.mtx | B10: 1 | D10: 27720684 | E10: 1.358776 | G10: 0.039487362 | H10: 0.041145802 | I10: 0.04029417 | J10: 0.040298939 | K10: 0.040371895 | L10: 0.04143095 | M10: 0.041602373 | N10: 0.041573763 | O10: 0.040261269 | P10: 0.041557789 | R10: =PERCENTILE(G10:P10,0.9) -> 0.041576624 | S10: =spmv_1!R$6/R10 -> 4.046375 | T10: =S10/4 -> 1.0115937
A11: ML_Geer.mtx | B11: 2 | D11: 27719328 | E11: 1.342717 | G11: 0.041122913 | H11: 0.041344166 | I11: 0.041503429 | J11: 0.041078568 | K11: 0.041470528 | L11: 0.0406425 | M11: 0.041496515 | N11: 0.0416224 | O11: 0.041588545 | P11: 0.041014671 | R11: =PERCENTILE(G11:P11,0.9) -> 0.04159193 | S11: =spmv_1!R$6/R11 -> 4.0448858 | T11: =S11/4 -> 1.0112215
A12: ML_Geer.mtx | B12: 3 | D12: 27719302 | E12: 1.375277 | G12: 0.039041042 | H12: 0.039819241 | I12: 0.040188551 | J12: 0.04093504 | K12: 0.040450096 | L12: 0.040946722 | M12: 0.040290594 | N12: 0.040420532 | O12: 0.040861368 | P12: 0.040155411 | R12: =PERCENTILE(G12:P12,0.9) -> 0.040936208 | S12: =spmv_1!R$6/R12 -> 4.1096774 | T12: =S12/4 -> 1.0274194
A15: Matrix | B15: Rank | D15: Local NNZ | E15: GFLOPS | G15: Iter_0 | H15: Iter_1 | I15: Iter_2 | J15: Iter_3 | K15: Iter_4 | L15: Iter_5 | M15: Iter_6 | N15: Iter_7 | O15: Iter_8 | P15: Iter_9 | R15: 90 percentile | S15: Speedup | T15: Efficiency
A16: msdoor.mtx | B16: 0 | D16: 5058715 | E16: 1.218674 | G16: 0.008655548 | H16: 0.008394241 | I16: 0.008255959 | J16: 0.008260012 | K16: 0.008267164 | L16: 0.008269072 | M16: 0.00818038 | N16: 0.008245945 | O16: 0.008247852 | P16: 0.008243799 | R16: =PERCENTILE(G16:P16,0.9) -> 0.0084203717 | S16: =spmv_1!R$10/R16 -> 4.1603537 | T16: =S16/4 -> 1.0400884
A17: msdoor.mtx | B17: 1 | D17: 5063792 | E17: 1.233866 | G17: 0.008527517 | H17: 0.008019209 | I17: 0.008064032 | J17: 0.008225679 | K17: 0.008230448 | L17: 0.008278131 | M17: 0.00825882 | N17: 0.007972002 | O17: 0.008184195 | P17: 0.008320093 | R17: =PERCENTILE(G17:P17,0.9) -> 0.0083408354 | S17: =spmv_1!R$10/R17 -> 4.2000259 | T17: =S17/4 -> 1.0500065
A18: msdoor.mtx | B18: 2 | D18: 5055857 | E18: 1.191625 | G18: 0.008817196 | H18: 0.008522272 | I18: 0.008379459 | J18: 0.008380413 | K18: 0.008482218 | L18: 0.008481503 | M18: 0.008460283 | N18: 0.008362055 | O18: 0.00843215 | P18: 0.008538961 | R18: =PERCENTILE(G18:P18,0.9) -> 0.0085667845 | S18: =spmv_1!R$10/R18 -> 4.0892501 | T18: =S18/4 -> 1.0223125
A19: msdoor.mtx | B19: 3 | D19: 5062571 | E19: 1.182219 | G19: 0.009032011 | H19: 0.008604527 | I19: 0.008483887 | J19: 0.008514404 | K19: 0.00847888 | L19: 0.008449078 | M19: 0.008575916 | N19: 0.008400202 | O19: 0.008520842 | P19: 0.008585453 | R19: =PERCENTILE(G19:P19,0.9) -> 0.0086472754 | S19: =spmv_1!R$10/R19 -> 4.0511864 | T19: =S19/4 -> 1.0127966
A22: Matrix | B22: Rank | D22: Local NNZ | E22: GFLOPS | G22: Iter_0 | H22: Iter_1 | I22: Iter_2 | J22: Iter_3 | K22: Iter_4 | L22: Iter_5 | M22: Iter_6 | N22: Iter_7 | O22: Iter_8 | P22: Iter_9 | R22: 90 percentile | S22: Speedup | T22: Efficiency
A23: nlpkkt240.mtx | B23: 0 | D23: 193615216 | E23: 1.055012 | G23: 0.36688709 | H23: 0.36687326 | I23: 0.36665082 | J23: 0.36680603 | K23: 0.36705065 | L23: 0.36734104 | M23: 0.36716509 | N23: 0.36757588 | O23: 0.36707592 | P23: 0.36696339 | R23: =PERCENTILE(G23:P23,0.9) -> 0.36736453 | S23: =spmv_1!R$14/R23 -> 3.0066707 | T23: =S23/4 -> 0.75166768
A24: nlpkkt240.mtx | B24: 1 | D24: 193620960 | E24: 1.056275 | G24: 0.37345839 | H24: 0.36486149 | I24: 0.36462617 | J24: 0.36412382 | K24: 0.36532783 | L24: 0.36488032 | M24: 0.3646574 | N24: 0.36500978 | O24: 0.37408137 | P24: 0.36508369 | R24: =PERCENTILE(G24:P24,0.9) -> 0.37352068 | S24: =spmv_1!R$14/R24 -> 2.9571165 | T24: =S24/4 -> 0.73927912
A25: nlpkkt240.mtx | B25: 2 | D25: 193620960 | E25: 1.053977 | G25: 0.37454653 | H25: 0.36519957 | I25: 0.36547661 | J25: 0.36511231 | K25: 0.36577225 | L25: 0.36573696 | M25: 0.36617899 | N25: 0.36590076 | O25: 0.37483931 | P25: 0.36533737 | R25: =PERCENTILE(G25:P25,0.9) -> 0.37457581 | S25: =spmv_1!R$14/R25 -> 2.9487867 | T25: =S25/4 -> 0.73719668
A26: nlpkkt240.mtx | B26: 3 | D26: 193615216 | E26: 1.034265 | G26: 0.37433481 | H26: 0.37416458 | I26: 0.37380743 | J26: 0.37423873 | K26: 0.37479711 | L26: 0.37439752 | M26: 0.3744576 | N26: 0.3745203 | O26: 0.37468505 | P26: 0.37461209 | R26: =PERCENTILE(G26:P26,0.9) -> 0.37469625 | S26: =spmv_1!R$14/R26 -> 2.9478388 | T26: =S26/4 -> 0.7369597
A29: Matrix | B29: Rank | D29: Local NNZ | E29: GFLOPS | G29: Iter_0 | H29: Iter_1 | I29: Iter_2 | J29: Iter_3 | K29: Iter_4 | L29: Iter_5 | M29: Iter_6 | N29: Iter_7 | O29: Iter_8 | P29: Iter_9 | R29: 90 percentile | S29: Speedup | T29: Efficiency
A30: Pflow_742.mtx | B30: 0 | D30: 9302103 | E30: 0.764497 | G30: 0.023035526 | H30: 0.024475813 | I30: 0.024579048 | J30: 0.0244627 | K30: 0.024162292 | L30: 0.024510622 | M30: 0.024620056 | N30: 0.024677992 | O30: 0.024659395 | P30: 0.02416873 | R30: =PERCENTILE(G30:P30,0.9) -> 0.024661255 | S30: =spmv_1!R$18/R30 -> 3.1441518 | T30: =S30/4 -> 0.78603795
A31: Pflow_742.mtx | B31: 1 | D31: 9184782 | E31: 1.262433 | G31: 0.018001318 | H31: 0.014500856 | I31: 0.014052153 | J31: 0.013979673 | K31: 0.014300108 | L31: 0.013938189 | M31: 0.014250994 | N31: 0.014009476 | O31: 0.01414752 | P31: 0.014328957 | R31: =PERCENTILE(G31:P31,0.9) -> 0.014850902 | S31: =spmv_1!R$18/R31 -> 5.221146 | T31: =S31/4 -> 1.3052865
A32: Pflow_742.mtx | B32: 2 | D32: 9138104 | E32: 0.778831 | G32: 0.019892454 | H32: 0.024363995 | I32: 0.02401042 | J32: 0.023626566 | K32: 0.023717165 | L32: 0.023770332 | M32: 0.023964167 | N32: 0.023531199 | O32: 0.023878336 | P32: 0.023907423 | R32: =PERCENTILE(G32:P32,0.9) -> 0.024045778 | S32: =spmv_1!R$18/R32 -> 3.2246297 | T32: =S32/4 -> 0.80615743
A33: Pflow_742.mtx | B33: 3 | D33: 9513472 | E33: 1.289487 | G33: 0.017922401 | H33: 0.014955282 | I33: 0.01444602 | J33: 0.014402151 | K33: 0.01418829 | L33: 0.014298677 | M33: 0.014585257 | N33: 0.014248848 | O33: 0.014042377 | P33: 0.014465094 | R33: =PERCENTILE(G33:P33,0.9) -> 0.015251994 | S33: =spmv_1!R$18/R33 -> 5.0838421 | T33: =S33/4 -> 1.2709605

Sheet spmv_8
A1: Matrix | B1: Rank | D1: Local NNZ | E1: GFLOPS | G1: Iter_0 | H1: Iter_1 | I1: Iter_2 | J1: Iter_3 | K1: Iter_4 | L1: Iter_5 | M1: Iter_6 | N1: Iter_7 | O1: Iter_8 | P1: Iter_9 | R1: 90 percentile | S1: Speedup | T1: Efficiency
A2: bmwcra_1.mtx | B2: 0 | D2: 1329644 | E2: 1.005305 | G2: 0.002890587 | H2: 0.002570629 | I2: 0.002589464 | J2: 0.002710342 | K2: 0.002684593 | L2: 0.002572536 | M2: 0.002524376 | N2: 0.002598286 | O2: 0.002640963 | P2: 0.002670765 | R2: =PERCENTILE(G2:P2,0.9) -> 0.0027283665 | S2: =spmv_1!R$2/R2 -> 6.3859633 | T2: =S2/8 -> 0.79824542
A3: bmwcra_1.mtx | B3: 1 | D3: 1332084 | E3: 0.966445 | G3: 0.002987623 | H3: 0.002701521 | I3: 0.002714396 | J3: 0.002835274 | K3: 0.002756119 | L3: 0.002753973 | M3: 0.002630472 | N3: 0.002732515 | O3: 0.002698898 | P3: 0.00275588 | R3: =PERCENTILE(G3:P3,0.9) -> 0.0028505089 | S3: =spmv_1!R$2/R3 -> 6.1123291 | T3: =S3/8 -> 0.76404113
A4: bmwcra_1.mtx | B4: 2 | D4: 1329679 | E4: 0.915288 | G4: 0.003011703 | H4: 0.00285697 | I4: 0.002855539 | J4: 0.002933741 | K4: 0.002861023 | L4: 0.002892971 | M4: 0.002884388 | N4: 0.00296855 | O4: 0.002873182 | P4: 0.002916813 | R4: =PERCENTILE(G4:P4,0.9) -> 0.0029728653 | S4: =spmv_1!R$2/R4 -> 5.8607594 | T4: =S4/8 -> 0.73259493
A5: bmwcra_1.mtx | B5: 3 | D5: 1331060 | E5: 0.670849 | G5: 0.003385067 | H5: 0.004009962 | I5: 0.004036903 | J5: 0.00406146 | K5: 0.004045486 | L5: 0.004056454 | M5: 0.00409174 | N5: 0.004016161 | O5: 0.003964424 | P5: 0.004015207 | R5: =PERCENTILE(G5:P5,0.9) -> 0.004064488 | S5: =spmv_1!R$2/R5 -> 4.2867019 | T5: =S5/8 -> 0.53583774
A6: bmwcra_1.mtx | B6: 4 | D6: 1329155 | E6: 0.909309 | G6: 0.00307107 | H6: 0.002937317 | I6: 0.002910376 | J6: 0.002880812 | K6: 0.00290966 | L6: 0.002882481 | M6: 0.002913475 | N6: 0.002882719 | O6: 0.002901077 | P6: 0.002945423 | R6: =PERCENTILE(G6:P6,0.9) -> 0.0029579877 | S6: =spmv_1!R$2/R6 -> 5.8902369 | T6: =S6/8 -> 0.73627962
A7: bmwcra_1.mtx | B7: 5 | D7: 1331420 | E7: 0.922542 | G7: 0.003094673 | H7: 0.002895832 | I7: 0.002940655 | J7: 0.002841473 | K7: 0.002847672 | L7: 0.002854824 | M7: 0.002920389 | N7: 0.002799273 | O7: 0.002782583 | P7: 0.002886772 | R7: =PERCENTILE(G7:P7,0.9) -> 0.0029560568 | S7: =spmv_1!R$2/R7 -> 5.8940844 | T7: =S7/8 -> 0.73676056
A8: bmwcra_1.mtx | B8: 6 | D8: 1329374 | E8: 0.923482 | G8: 0.003043175 | H8: 0.002840757 | I8: 0.002899885 | J8: 0.002848387 | K8: 0.002798319 | L8: 0.002793789 | M8: 0.00289607 | N8: 0.002936602 | O8: 0.002873421 | P8: 0.002860069 | R8: =PERCENTILE(G8:P8,0.9) -> 0.0029472593 | S8: =spmv_1!R$2/R8 -> 5.9116781 | T8: =S8/8 -> 0.73895977
A9: bmwcra_1.mtx | B9: 7 | D9: 1331586 | E9: 0.960873 | G9: 0.003015518 | H9: 0.002788544 | I9: 0.002831936 | J9: 0.002766371 | K9: 0.002727032 | L9: 0.002726078 | M9: 0.002800703 | N9: 0.002728224 | O9: 0.002656221 | P9: 0.002675533 | R9: =PERCENTILE(G9:P9,0.9) -> 0.0028502942 | S9: =spmv_1!R$2/R9 -> 6.1127895 | T9: =S9/8 -> 0.76409868
A12: Matrix | B12: Rank | D12: Local NNZ | E12: GFLOPS | G12: Iter_0 | H12: Iter_1 | I12: Iter_2 | J12: Iter_3 | K12: Iter_4 | L12: Iter_5 | M12: Iter_6 | N12: Iter_7 | O12: Iter_8 | P12: Iter_9 | R12: 90 percentile | S12: Speedup | T12: Efficiency
A13: ML_Geer.mtx | B13: 0 | D13: 13861994 | E13: 0.954163 | G13: 0.028968573 | H13: 0.028804541 | I13: 0.02906394 | J13: 0.02913785 | K13: 0.029173613 | L13: 0.029560328 | M13: 0.028664351 | N13: 0.029616833 | O13: 0.028991222 | P13: 0.028577089 | R13: =PERCENTILE(G13:P13,0.9) -> 0.029565978 | S13: =spmv_1!R$6/R13 -> 5.6901418 | T13: =S13/8 -> 0.71126773
A14: ML_Geer.mtx | B14: 1 | D14: 13862028 | E14: 0.926703 | G14: 0.029749393 | H14: 0.030009747 | I14: 0.03088522 | J14: 0.029790163 | K14: 0.030053377 | L14: 0.029530764 | M14: 0.029666662 | N14: 0.029775381 | O14: 0.029995203 | P14: 0.029712677 | R14: =PERCENTILE(G14:P14,0.9) -> 0.030136561 | S14: =spmv_1!R$6/R14 -> 5.582409 | T14: =S14/8 -> 0.69780112
A15: ML_Geer.mtx | B15: 2 | D15: 13860012 | E15: 0.917654 | G15: 0.029976845 | H15: 0.029892445 | I15: 0.030890465 | J15: 0.029735804 | K15: 0.030831099 | L15: 0.030782461 | M15: 0.030320883 | N15: 0.029611588 | O15: 0.030029058 | P15: 0.030004263 | R15: =PERCENTILE(G15:P15,0.9) -> 0.030837036 | S15: =spmv_1!R$6/R15 -> 5.4556026 | T15: =S15/8 -> 0.68195032
A16: ML_Geer.mtx | B16: 3 | D16: 13859966 | E16: 0.948994 | G16: 0.028946161 | H16: 0.028712988 | I16: 0.03059411 | J16: 0.028787136 | K16: 0.029452324 | L16: 0.029074907 | M16: 0.028989553 | N16: 0.029169559 | O16: 0.029422522 | P16: 0.028948784 | R16: =PERCENTILE(G16:P16,0.9) -> 0.029566503 | S16: =spmv_1!R$6/R16 -> 5.690041 | T16: =S16/8 -> 0.71125512
A17: ML_Geer.mtx | B17: 4 | D17: 13858664 | E17: 0.987626 | G17: 0.028185129 | H17: 0.028303385 | I17: 0.029328108 | J17: 0.028196573 | K17: 0.027871132 | L17: 0.027477264 | M17: 0.027676344 | N17: 0.027784824 | O17: 0.027963877 | P17: 0.027859449 | R17: =PERCENTILE(G17:P17,0.9) -> 0.028405857 | S17: =spmv_1!R$6/R17 -> 5.9225324 | T17: =S17/8 -> 0.74031655
A18: ML_Geer.mtx | B18: 5 | D18: 13858656 | E18: 0.939066 | G18: 0.030014992 | H18: 0.028877258 | I18: 0.029251575 | J18: 0.029257536 | K18: 0.030059338 | L18: 0.029464483 | M18: 0.029713631 | N18: 0.029369831 | O18: 0.029931068 | P18: 0.029218435 | R18: =PERCENTILE(G18:P18,0.9) -> 0.030019427 | S18: =spmv_1!R$6/R18 -> 5.6041913 | T18: =S18/8 -> 0.70052392
A19: ML_Geer.mtx | B19: 6 | D19: 13859316 | E19: 0.951221 | G19: 0.029158115 | H19: 0.028816223 | I19: 0.028887987 | J19: 0.028783321 | K19: 0.029579639 | L19: 0.029793501 | M19: 0.029111385 | N19: 0.029226303 | O19: 0.029145241 | P19: 0.028898716 | R19: =PERCENTILE(G19:P19,0.9) -> 0.029601025 | S19: =spmv_1!R$6/R19 -> 5.6834049 | T19: =S19/8 -> 0.71042561
A20: ML_Geer.mtx | B20: 7 | D20: 13859336 | E20: 0.962114 | G20: 0.028923512 | H20: 0.028858423 | I20: 0.02867198 | J20: 0.028305292 | K20: 0.029077768 | L20: 0.028938293 | M20: 0.028995275 | N20: 0.028527021 | O20: 0.028982639 | P20: 0.028821468 | R20: =PERCENTILE(G20:P20,0.9) -> 0.029003524 | S20: =spmv_1!R$6/R20 -> 5.8004885 | T20: =S20/8 -> 0.72506107
A23: Matrix | B23: Rank | D23: Local NNZ | E23: GFLOPS | G23: Iter_0 | H23: Iter_1 | I23: Iter_2 | J23: Iter_3 | K23: Iter_4 | L23: Iter_5 | M23: Iter_6 | N23: Iter_7 | O23: Iter_8 | P23: Iter_9 | R23: 90 percentile | S23: Speedup | T23: Efficiency
A24: msdoor.mtx | B24: 0 | D24: 2537442 | E24: 0.719383 | G24: 0.00718236 | H24: 0.006985664 | I24: 0.007139206 | J24: 0.007087469 | K24: 0.007041454 | L24: 0.006997585 | M24: 0.006931305 | N24: 0.006893396 | O24: 0.007231712 | P24: 0.007054806 | R24: =PERCENTILE(G24:P24,0.9) -> 0.0071872952 | S24: =spmv_1!R$10/R24 -> 4.8741179 | T24: =S24/8 -> 0.60926474
A25: msdoor.mtx | B25: 1 | D25: 2540545 | E25: 0.676775 | G25: 0.007555008 | H25: 0.007407188 | I25: 0.00757432 | J25: 0.007582903 | K25: 0.007510662 | L25: 0.007458925 | M25: 0.007474184 | N25: 0.007558346 | O25: 0.00754118 | P25: 0.007415295 | R25: =PERCENTILE(G25:P25,0.9) -> 0.0075751783 | S25: =spmv_1!R$10/R25 -> 4.6245412 | T25: =S25/8 -> 0.57806765
A26: msdoor.mtx | B26: 2 | D26: 2535823 | E26: 0.733584 | G26: 0.007042885 | H26: 0.006829262 | I26: 0.00698328 | J26: 0.006916046 | K26: 0.006920576 | L26: 0.006844521 | M26: 0.006819725 | N26: 0.006781816 | O26: 0.007096529 | P26: 0.006900549 | R26: =PERCENTILE(G26:P26,0.9) -> 0.0070482494 | S26: =spmv_1!R$10/R26 -> 4.9702731 | T26: =S26/8 -> 0.62128414
A27: msdoor.mtx | B27: 3 | D27: 2539771 | E27: 0.676809 | G27: 0.007547855 | H27: 0.007393837 | I27: 0.007569551 | J27: 0.007547617 | K27: 0.007504225 | L27: 0.007478476 | M27: 0.007471323 | N27: 0.007567406 | O27: 0.007529736 | P27: 0.007441282 | R27: =PERCENTILE(G27:P27,0.9) -> 0.0075676205 | S27: =spmv_1!R$10/R27 -> 4.6291598 | T27: =S27/8 -> 0.57864497
A28: msdoor.mtx | B28: 4 | D28: 2521273 | E28: 0.678743 | G28: 0.007388115 | H28: 0.007325172 | I28: 0.007496357 | J28: 0.007507801 | K28: 0.007436275 | L28: 0.007375717 | M28: 0.007418871 | N28: 0.007483959 | O28: 0.007464409 | P28: 0.007395744 | R28: =PERCENTILE(G28:P28,0.9) -> 0.0074975014 | S28: =spmv_1!R$10/R28 -> 4.6724532 | T28: =S28/8 -> 0.58405665
A29: msdoor.mtx | B29: 5 | D29: 2523247 | E29: 0.69478 | G29: 0.007354736 | H29: 0.007111073 | I29: 0.007335424 | J29: 0.007295609 | K29: 0.007286549 | L29: 0.007172823 | M29: 0.007302999 | N29: 0.007360935 | O29: 0.007215738 | P29: 0.007198572 | R29: =PERCENTILE(G29:P29,0.9) -> 0.0073553559 | S29: =spmv_1!R$10/R29 -> 4.7627504 | T29: =S29/8 -> 0.5953438
A30: msdoor.mtx | B30: 6 | D30: 2520034 | E30: 0.684758 | G30: 0.0075109 | H30: 0.007202864 | I30: 0.007403612 | J30: 0.007415295 | K30: 0.007380247 | L30: 0.007270098 | M30: 0.007382631 | N30: 0.007407427 | O30: 0.007366419 | P30: 0.007264137 | R30: =PERCENTILE(G30:P30,0.9) -> 0.0074248555 | S30: =spmv_1!R$10/R30 -> 4.7181692 | T30: =S30/8 -> 0.58977115
A31: msdoor.mtx | B31: 7 | D31: 2522800 | E31: 0.681384 | G31: 0.007567883 | H31: 0.007241726 | I31: 0.007460594 | J31: 0.007422447 | K31: 0.007376671 | L31: 0.007327557 | M31: 0.007377863 | N31: 0.007489443 | O31: 0.007452488 | P31: 0.007332563 | R31: =PERCENTILE(G31:P31,0.9) -> 0.007497287 | S31: =spmv_1!R$10/R31 -> 4.6725868 | T31: =S31/8 -> 0.58407335
A34: Matrix | B34: Rank | D34: Local NNZ | E34: GFLOPS | G34: Iter_0 | H34: Iter_1 | I34: Iter_2 | J34: Iter_3 | K34: Iter_4 | L34: Iter_5 | M34: Iter_6 | N34: Iter_7 | O34: Iter_8 | P34: Iter_9 | R34: 90 percentile | S34: Speedup | T34: Efficiency
A35: nlpkkt240.mtx | B35: 0 | D35: 96804736 | E35: 0.540833 | G35: 0.35087204 | H35: 0.35975385 | I35: 0.35556269 | J35: 0.35904813 | K35: 0.35751677 | L35: 0.36080313 | M35: 0.35578203 | N35: 0.36332107 | O35: 0.36066246 | P35: 0.3565166 | R35: =PERCENTILE(G35:P35,0.9) -> 0.36105492 | S35: =spmv_1!R$14/R35 -> 3.0592137 | T35: =S35/8 -> 0.38240171
A36: nlpkkt240.mtx | B36: 1 | D36: 96810480 | E36: 0.569083 | G36: 0.33304286 | H36: 0.34217596 | I36: 0.33784413 | J36: 0.34111142 | K36: 0.33971143 | L36: 0.34298706 | M36: 0.33792019 | N36: 0.3457613 | O36: 0.34307265 | P36: 0.33870292 | R36: =PERCENTILE(G36:P36,0.9) -> 0.34334152 | S36: =spmv_1!R$14/R36 -> 3.2170422 | T36: =S36/8 -> 0.40213028
A37: nlpkkt240.mtx | B37: 2 | D37: 96810480 | E37: 0.521776 | G37: 0.33020496 | H37: 0.3386116 | I37: 0.33476901 | J37: 0.33758998 | K37: 0.33673406 | L37: 0.33995676 | M37: 0.41065383 | N37: 0.43166566 | O37: 0.39621687 | P37: 0.45440674 | R37: =PERCENTILE(G37:P37,0.9) -> 0.43393977 | S37: =spmv_1!R$14/R37 -> 2.5453859 | T37: =S37/8 -> 0.31817324
A38: nlpkkt240.mtx | B38: 3 | D38: 96810480 | E38: 0.544176 | G38: 0.3478899 | H38: 0.35670686 | I38: 0.35223484 | J38: 0.35552216 | K38: 0.35422444 | L38: 0.35733986 | M38: 0.36276865 | N38: 0.35980701 | O38: 0.35780048 | P38: 0.35376144 | R38: =PERCENTILE(G38:P38,0.9) -> 0.36010318 | S38: =spmv_1!R$14/R38 -> 3.0672991 | T38: =S38/8 -> 0.38341239
A39: nlpkkt240.mtx | B39: 4 | D39: 96810480 | E39: 0.55186 | G39: 0.34732914 | H39: 0.35514903 | I39: 0.35094595 | J39: 0.35904431 | K39: 0.35257649 | L39: 0.35183406 | M39: 0.34662962 | N39: 0.33836317 | O39: 0.35263681 | P39: 0.35400867 | R39: =PERCENTILE(G39:P39,0.9) -> 0.35553856 | S39: =spmv_1!R$14/R39 -> 3.106679 | T39: =S39/8 -> 0.38833487
A40: nlpkkt240.mtx | B40: 5 | D40: 96810480 | E40: 0.528276 | G40: 0.3601861 | H40: 0.36947799 | I40: 0.36525083 | J40: 0.36855888 | K40: 0.36744475 | L40: 0.37051249 | M40: 0.36336017 | N40: 0.36315513 | O40: 0.37060618 | P40: 0.36659813 | R40: =PERCENTILE(G40:P40,0.9) -> 0.37052186 | S40: =spmv_1!R$14/R40 -> 2.98105 | T40: =S40/8 -> 0.37263124
A41: nlpkkt240.mtx | B41: 6 | D41: 96810480 | E41: 0.560858 | G41: 0.35186911 | H41: 0.34324908 | I41: 0.35546064 | J41: 0.34613395 | K41: 0.34253478 | L41: 0.34023595 | M41: 0.34614563 | N41: 0.34407306 | O41: 0.34089565 | P41: 0.34162712 | R41: =PERCENTILE(G41:P41,0.9) -> 0.35222826 | S41: =spmv_1!R$14/R41 -> 3.135876 | T41: =S41/8 -> 0.39198451
A42: nlpkkt240.mtx | B42: 7 | D42: 96804736 | E42: 0.568868 | G42: 0.34137845 | H42: 0.34200644 | I42: 0.34495783 | J42: 0.34035158 | K42: 0.33650279 | L42: 0.33825517 | M42: 0.33675289 | N42: 0.34420204 | O42: 0.33967805 | P42: 0.33933401 | R42: =PERCENTILE(G42:P42,0.9) -> 0.34427762 | S42: =spmv_1!R$14/R42 -> 3.208295 | T42: =S42/8 -> 0.40103687
A45: Matrix | B45: Rank | D45: Local NNZ | E45: GFLOPS | G45: Iter_0 | H45: Iter_1 | I45: Iter_2 | J45: Iter_3 | K45: Iter_4 | L45: Iter_5 | M45: Iter_6 | N45: Iter_7 | O45: Iter_8 | P45: Iter_9 | R45: 90 percentile | S45: Speedup | T45: Efficiency
A46: Pflow_742.mtx | B46: 0 | D46: 4650821 | E46: 0.864352 | G46: 0.010956049 | H46: 0.01047349 | I46: 0.010639906 | J46: 0.010870934 | K46: 0.010637283 | L46: 0.010643482 | M46: 0.010798693 | N46: 0.010700226 | O46: 0.010910988 | P46: 0.01098299 | R46: =PERCENTILE(G46:P46,0.9) -> 0.010958743 | S46: =spmv_1!R$18/R46 -> 7.075513 | T46: =S46/8 -> 0.88443912
A47: Pflow_742.mtx | B47: 1 | D47: 4591501 | E47: 0.849752 | G47: 0.010844469 | H47: 0.010603189 | I47: 0.010851145 | J47: 0.010784864 | K47: 0.010893106 | L47: 0.010707378 | M47: 0.010877609 | N47: 0.010699034 | O47: 0.010868549 | P47: 0.010937452 | R47: =PERCENTILE(G47:P47,0.9) -> 0.010897541 | S47: =spmv_1!R$18/R47 -> 7.1152503 | T47: =S47/8 -> 0.88940628
A48: Pflow_742.mtx | B48: 2 | D48: 4568376 | E48: 0.864408 | G48: 0.010553122 | H48: 0.010435104 | I48: 0.010332823 | J48: 0.010704041 | K48: 0.010693073 | L48: 0.010511637 | M48: 0.010508537 | N48: 0.010475159 | O48: 0.010749817 | P48: 0.010736227 | R48: =PERCENTILE(G48:P48,0.9) -> 0.010737586 | S48: =spmv_1!R$18/R48 -> 7.221244 | T48: =S48/8 -> 0.9026555
...

Sheet spmv_1x16
A1: Matrix | B1: Rank | D1: Local NNZ | E1: GFLOPS | G1: Iter_0 | H1: Iter_1 | I1: Iter_2 | J1: Iter_3 | K1: Iter_4 | L1: Iter_5 | M1: Iter_6 | N1: Iter_7 | O1: Iter_8 | P1: Iter_9 | R1: 90 percentile | S1: Speedup | T1: Efficiency
A2: bmwcra_1.mtx | B2: 0 | D2: 666452 | E2: 0.902905 | G2: 0.001858473 | H2: 0.001502752 | I2: 0.001444578 | J2: 0.001453638 | K2: 0.00143981 | L2: 0.001410961 | M2: 0.001428843 | N2: 0.001447916 | O2: 0.00141716 | P2: 0.001358271 | R2: =PERCENTILE(G2:P2,0.9) -> 0.0015383241 | S2: =spmv_1!R$2/R2 -> 11.326123 | T2: =S2/16 -> 0.7078827
A3: bmwcra_1.mtx | B3: 1 | D3: 667346 | E3: 0.856621 | G3: 0.001888037 | H3: 0.001577377 | I3: 0.00152564 | J3: 0.001552582 | K3: 0.001521826 | L3: 0.001490831 | M3: 0.001512766 | N3: 0.001534462 | O3: 0.00150156 | P3: 0.001475811 | R3: =PERCENTILE(G3:P3,0.9) -> 0.001608443 | S3: =spmv_1!R$2/R3 -> 10.832369 | T3: =S3/16 -> 0.67702307
A4: bmwcra_1.mtx | B4: 2 | D4: 665088 | E4: 0.862633 | G4: 0.00182271 | H4: 0.001541615 | I4: 0.001508474 | J4: 0.001609325 | K4: 0.00153017 | L4: 0.001502275 | M4: 0.001424074 | N4: 0.001498222 | O4: 0.00150013 | P4: 0.001482964 | R4: =PERCENTILE(G4:P4,0.9) -> 0.0016306635 | S4: =spmv_1!R$2/R4 -> 10.68476 | T4: =S4/16 -> 0.66779751
A5: bmwcra_1.mtx | B5: 3 | D5: 663375 | E5: 0.88403 | G5: 0.001833677 | H5: 0.001581907 | I5: 0.001498222 | J5: 0.001498699 | K5: 0.001442432 | L5: 0.001420259 | M5: 0.001441002 | N5: 0.001424789 | O5: 0.001442194 | P5: 0.001424789 | R5: =PERCENTILE(G5:P5,0.9) -> 0.001607084 | S5: =spmv_1!R$2/R5 -> 10.841529 | T5: =S5/16 -> 0.67759559
A6: bmwcra_1.mtx | B6: 4 | D6: 662698 | E6: 0.843082 | G6: 0.001921177 | H6: 0.001598358 | I6: 0.001549482 | J6: 0.001547098 | K6: 0.001518965 | L6: 0.001498461 | M6: 0.001532078 | N6: 0.001554966 | O6: 0.001524687 | P6: 0.001475573 | R6: =PERCENTILE(G6:P6,0.9) -> 0.0016306399 | S6: =spmv_1!R$2/R6 -> 10.684915 | T6: =S6/16 -> 0.66780717
A7: bmwcra_1.mtx | B7: 5 | D7: 665594 | E7: 0.854111 | G7: 0.001941681 | H7: 0.00158906 | I7: 0.001542807 | J7: 0.001522779 | K7: 0.00151968 | L7: 0.001501322 | M7: 0.001489401 | N7: 0.00152421 | O7: 0.001499891 | P7: 0.00145483 | R7: =PERCENTILE(G7:P7,0.9) -> 0.0016243221 | S7: =spmv_1!R$2/R7 -> 10.726474 | T7: =S7/16 -> 0.67040461
A8: bmwcra_1.mtx | B8: 6 | D8: 665712 | E8: 0.794084 | G8: 0.002165794 | H8: 0.001710653 | I8: 0.001644373 | J8: 0.001621008 | K8: 0.001639366 | L8: 0.001589298 | M8: 0.001587629 | N8: 0.001589537 | O8: 0.001618624 | P8: 0.001600504 | R8: =PERCENTILE(G8:P8,0.9) -> 0.0017561671 | S8: =spmv_1!R$2/R8 -> 9.9211791 | T8: =S8/16 -> 0.6200737
A9: bmwcra_1.mtx | B9: 7 | D9: 666565 | E9: 0.795452 | G9: 0.00215435 | H9: 0.001705408 | I9: 0.001640081 | J9: 0.001612663 | K9: 0.001604795 | L9: 0.001595974 | M9: 0.001605988 | N9: 0.001617432 | O9: 0.001618862 | P9: 0.001603842 | R9: =PERCENTILE(G9:P9,0.9) -> 0.0017503022 | S9: =spmv_1!R$2/R9 -> 9.954423 | T9: =S9/16 -> 0.62215143
A10: bmwcra_1.mtx | B10: 8 | D10: 663192 | E10: 0.847773 | G10: 0.001969576 | H10: 0.001593351 | I10: 0.001531124 | J10: 0.001517296 | K10: 0.001521111 | L10: 0.001496077 | M10: 0.001477957 | N10: 0.001543045 | O10: 0.001518965 | P10: 0.001477003 | R10: =PERCENTILE(G10:P10,0.9) -> 0.0016309735 | S10: =spmv_1!R$2/R10 -> 10.682729 | T10: =S10/16 -> 0.66767058
A11: bmwcra_1.mtx | B11: 9 | D11: 664738 | E11: 0.792866 | G11: 0.00220108 | H11: 0.001708269 | I11: 0.001636505 | J11: 0.001603365 | K11: 0.001607656 | L11: 0.001589775 | M11: 0.001567602 | N11: 0.001629353 | O11: 0.001617193 | P11: 0.00160718 | R11: =PERCENTILE(G11:P11,0.9) -> 0.0017575501 | S11: =spmv_1!R$2/R11 -> 9.9133723 | T11: =S11/16 -> 0.61958577
A12: bmwcra_1.mtx | B12: 10 | D12: 664591 | E12: 0.804983 | G12: 0.002147436 | H12: 0.001692295 | I12: 0.001617193 | J12: 0.001583815 | K12: 0.001590967 | L12: 0.001574755 | M12: 0.001539707 | N12: 0.001582384 | O12: 0.001588106 | P12: 0.001595259 | R12: =PERCENTILE(G12:P12,0.9) -> 0.0017378091 | S12: =spmv_1!R$2/R12 -> 10.025985 | T12: =S12/16 -> 0.62662408
A13: bmwcra_1.mtx | B13: 11 | D13: 667685 | E13: 0.815015 | G13: 0.002134085 | H13: 0.001677036 | I13: 0.001599789 | J13: 0.001579523 | K13: 0.001587152 | L13: 0.001555443 | M13: 0.001526594 | N13: 0.001577377 | O13: 0.001583815 | P13: 0.001563787 | R13: =PERCENTILE(G13:P13,0.9) -> 0.0017227409 | S13: =spmv_1!R$2/R13 -> 10.113679 | T13: =S13/16 -> 0.63210494
... A17: bmwcra_1.mtx | B17: 15 | D17: 665021 | E17: 0.91388 | G17: 0.001886606 | H17: 0.001487017 | I17: 0.001413822 | J17: 0.001422882 | K17: 0.001400471 | L17: 0.001398802 | M17: 0.001393318 | N17: 0.001398087 | O17: 0.00139308 | P17: 0.001359701 | R17: =PERCENTILE(G17:P17,0.9) -> 0.0015269759 | S17: =spmv_1!R$2/R17 -> 11.410297 | T17: =S17/16 -> 0.71314356
A20: Matrix | B20: Rank | D20: Local NNZ | E20: GFLOPS | G20: Iter_0 | H20: Iter_1 | I20: Iter_2 | J20: Iter_3 | K20: Iter_4 | L20: Iter_5 | M20: Iter_6 | N20: Iter_7 | O20: Iter_8 | P20: Iter_9 | R20: 90 percentile | S20: Speedup | T20: Efficiency
A21: ML_Geer.mtx | B21: 0 | D21: 6930698 | E21: 0.848363 | G21: 0.017124891 | H21: 0.016302109 | I21: 0.016746998 | J21: 0.016113281 | K21: 0.016448498 | L21: 0.016185999 | M21: 0.016110182 | N21: 0.016327143 | O21: 0.015980005 | P21: 0.016050816 | R21: =PERCENTILE(G21:P21,0.9) -> 0.016784787 | S21: =spmv_1!R$6/R21 -> 10.023041 | T21: =S21/16 -> 0.62644006
A22: ML_Geer.mtx | B22: 1 | D22: 6930722 | E22: 0.839847 | G22: 0.017216206 | H22: 0.016564608 | I22: 0.016758204 | J22: 0.016250372 | K22: 0.01646018 | L22: 0.016593695 | M22: 0.016321182 | N22: 0.016588926 | O22: 0.01614356 | P22: 0.016150236 | R22: =PERCENTILE(G22:P22,0.9) -> 0.016804004 | S22: =spmv_1!R$6/R22 -> 10.011579 | T22: =S22/16 -> 0.62572367
A23: ML_Geer.mtx | B23: 2 | D23: 6929254 | E23: 0.840313 | G23: 0.017202377 | H23: 0.016592741 | I23: 0.016732216 | J23: 0.016308308 | K23: 0.016323566 | L23: 0.016554832 | M23: 0.016343117 | N23: 0.016693592 | O23: 0.01607585 | P23: 0.016094208 | R23: =PERCENTILE(G23:P23,0.9) -> 0.016779232 | S23: =spmv_1!R$6/R23 -> 10.026359 | T23: =S23/16 -> 0.62664746
A24: ML_Geer.mtx | B24: 3 | D24: 6929236 | E24: 0.796413 | G24: 0.018392324 | H24: 0.018260479 | I24: 0.017565727 | J24: 0.017082691 | K24: 0.017115355 | L24: 0.017227173 | M24: 0.017108679 | N24: 0.017472744 | O24: 0.016963482 | P24: 0.016822577 | R24: =PERCENTILE(G24:P24,0.9) -> 0.018273663 | S24: =spmv_1!R$6/R24 -> 9.2063975 | T24: =S24/16 -> 0.57539985
A25: ML_Geer.mtx | B25: 4 | D25: 6928044 | E25: 0.782052 | G25: 0.018761873 | H25: 0.01836586 | I25: 0.01806736 | J25: 0.017349005 | K25: 0.017533541 | L25: 0.017535448 | M25: 0.017365694 | N25: 0.017584801 | O25: 0.017320156 | P25: 0.017292261 | R25: =PERCENTILE(G25:P25,0.9) -> 0.018405461 | S25: =spmv_1!R$6/R25 -> 9.1404724 | T25: =S25/16 -> 0.57127952
A26: ML_Geer.mtx | B26: 5 | D26: 6928026 | E26: 0.769824 | G26: 0.019035578 | H26: 0.018644094 | I26: 0.018402338 | J26: 0.017542124 | K26: 0.017742872 | L26: 0.017816544 | M26: 0.017645121 | N26: 0.017925024 | O26: 0.017738819 | P26: 0.017497301 | R26: =PERCENTILE(G26:P26,0.9) -> 0.018683242 | S26: =spmv_1!R$6/R26 -> 9.0045725 | T26: =S26/16 -> 0.56278578
A27: ML_Geer.mtx | B27: 6 | D27: 6929656 | E27: 0.805515 | G27: 0.017955542 | H27: 0.017482758 | I27: 0.017612457 | J27: 0.016933203 | K27: 0.017041922 | L27: 0.017114162 | M27: 0.016967297 | N27: 0.017114162 | O27: 0.016964436 | P27: 0.016869307 | R27: =PERCENTILE(G27:P27,0.9) -> 0.017646766 | S27: =spmv_1!R$6/R27 -> 9.5334531 | T27: =S27/16 -> 0.59584082
A28: ML_Geer.mtx | B28: 7 | D28: 6929668 | E28: 0.764232 | G28: 0.018911123 | H28: 0.018769503 | I28: 0.018535614 | J28: 0.017800331 | K28: 0.017775297 | L28: 0.018073797 | M28: 0.017870426 | N28: 0.018007994 | O28: 0.017759562 | P28: 0.017846107 | R28: =PERCENTILE(G28:P28,0.9) -> 0.018783665 | S28: =spmv_1!R$6/R28 -> 8.9564316 | T28: =S28/16 -> 0.55977697
A29: ML_Geer.mtx | B29: 8 | D29: 6931296 | E29: 0.805749 | G29: 0.018004894 | H29: 0.017374277 | I29: 0.017541409 | J29: 0.0170753 | K29: 0.017030716 | L29: 0.016992807 | M29: 0.017010212 | N29: 0.017044783 | O29: 0.016982794 | P29: 0.016988754 | R29: =PERCENTILE(G29:P29,0.9) -> 0.017587757 | S29: =spmv_1!R$6/R29 -> 9.5654384 | T29: =S29/16 -> 0.5978399
A30: ML_Geer.mtx | B30: 9 | D30: 6931306 | E30: 0.778316 | G30: 0.018324375 | H30: 0.017689943 | I30: 0.018156767 | J30: 0.017914057 | K30: 0.017942667 | L30: 0.017472267 | M30: 0.017761469 | N30: 0.017574787 | O30: 0.017702818 | P30: 0.017571211 | R30: =PERCENTILE(G30:P30,0.9) -> 0.018173528 | S30: =spmv_1!R$6/R30 -> 9.2571246 | T30: =S30/16 -> 0.57857029
A31: ML_Geer.mtx | B31: 10 | D31: 6930758 | E31: 0.774436 | G31: 0.018869162 | H31: 0.01831007 | I31: 0.01841855 | J31: 0.017719746 | K31: 0.017807961 | L31: 0.01775074 | M31: 0.017526627 | N31: 0.017482281 | O31: 0.017547369 | P31: 0.017555952 | R31: =PERCENTILE(G31:P31,0.9) -> 0.018463611 | S31: =spmv_1!R$6/R31 -> 9.1116851 | T31: =S31/16 -> 0.56948032
A32: ML_Geer.mtx | B32: 11 | D32: 6930730 | E32: 0.819032 | G32: 0.017158508 | H32: 0.016513586 | I32: 0.01784277 | J32: 0.017043591 | K32: 0.016719341 | L32: 0.016804457 | M32: 0.01659584 | N32: 0.016535282 | O32: 0.016892672 | P32: 0.017135859 | R32: =PERCENTILE(G32:P32,0.9) -> 0.017226934 | S32: =spmv_1!R$6/R32 -> 9.7657894 | T32: =S32/16 -> 0.61036183
... A36: ML_Geer.mtx | B36: 15 | D36: 6929668 | E36: 0.847068 | G36: 0.017115831 | H36: 0.016447067 | I36: 0.016691923 | J36: 0.016208887 | K36: 0.016457796 | L36: 0.016236305 | M36: 0.016199827 | N36: 0.016085386 | O36: 0.016178131 | P36: 0.01599431 | R36: =PERCENTILE(G36:P36,0.9) -> 0.016734314 | S36: =spmv_1!R$6/R36 -> 10.053272 | T36: =S36/16 -> 0.62832951
A39: Matrix | B39: Rank | D39: Local NNZ | E39: GFLOPS | G39: Iter_0 | H39: Iter_1 | I39: Iter_2 | J39: Iter_3 | K39: Iter_4 | L39: Iter_5 | M39: Iter_6 | N39: Iter_7 | O39: Iter_8 | P39: Iter_9 | R39: 90 percentile | S39: Speedup | T39: Efficiency
A40: msdoor.mtx | B40: 0 | D40: 1267995 | E40: 0.521124 | G40: 0.005250216 | H40: 0.00488472 | I40: 0.004750967 | J40: 0.004835367 | K40: 0.00488019 | L40: 0.004862547 | M40: 0.00483799 | N40: 0.004754305 | O40: 0.004785776 | P40: 0.004821777 | R40: =PERCENTILE(G40:P40,0.9) -> 0.0049212696 | S40: =spmv_1!R$10/R40 -> 7.1184323 | T40: =S40/16 -> 0.44490202
A41: msdoor.mtx | B41: 1 | D41: 1268949 | E41: 0.480398 | G41: 0.005649567 | H41: 0.005270958 | I41: 0.005256176 | J41: 0.005268574 | K41: 0.005316019 | L41: 0.005225182 | M41: 0.005259514 | N41: 0.005258322 | O41: 0.005182266 | P41: 0.00514245 | R41: =PERCENTILE(G41:P41,0.9) -> 0.0053493738 | S41: =spmv_1!R$10/R41 -> 6.5487524 | T41: =S41/16 -> 0.40929702
A42: msdoor.mtx | B42: 2 | D42: 1266254 | E42: 0.469079 | G42: 0.005773783 | H42: 0.005365133 | I42: 0.00538826 | J42: 0.005402327 | K42: 0.005347729 | L42: 0.005341291 | M42: 0.005362034 | N42: 0.005423784 | O42: 0.005271435 | P42: 0.005313158 | R42: =PERCENTILE(G42:P42,0.9) -> 0.0054587839 | S42: =spmv_1!R$10/R42 -> 6.4174961 | T42: =S42/16 -> 0.40109351
A43: msdoor.mtx | B43: 3 | D43: 1268739 | E43: 0.48934 | G43: 0.005571842 | H43: 0.005153656 | I43: 0.005187273 | J43: 0.005172729 | K43: 0.005144119 | L43: 0.005158186 | M43: 0.005116224 | N43: 0.005172729 | O43: 0.005066395 | P43: 0.005111933 | R43: =PERCENTILE(G43:P43,0.9) -> 0.0052257299 | S43: =spmv_1!R$10/R43 -> 6.7036998 | T43: =S43/16 -> 0.41898124
A44: msdoor.mtx | B44: 4 | D44: 1260291 | E44: 0.455803 | G44: 0.005975246 | H44: 0.005470514 | I44: 0.005532503 | J44: 0.005506754 | K44: 0.005487919 | L44: 0.00551486 | M44: 0.005458593 | N44: 0.005534649 | O44: 0.005393744 | P44: 0.005424976 | R44: =PERCENTILE(G44:P44,0.9) -> 0.0055787087 | S44: =spmv_1!R$10/R44 -> 6.27954 | T44: =S44/16 -> 0.39247125
A45: msdoor.mtx | B45: 5 | D45: 1261447 | E45: 0.473335 | G45: 0.005719185 | H45: 0.005408764 | I45: 0.005375862 | J45: 0.005288363 | K45: 0.005096674 | L45: 0.005385399 | M45: 0.005230188 | N45: 0.005326271 | O45: 0.005259991 | P45: 0.005209684 | R45: =PERCENTILE(G45:P45,0.9) -> 0.0054398061 | S45: =spmv_1!R$10/R45 -> 6.4398847 | T45: =S45/16 -> 0.4024928
A46: msdoor.mtx | B46: 6 | D46: 1260486 | E46: 0.465161 | G46: 0.005811214 | H46: 0.005425692 | I46: 0.005472183 | J46: 0.005418062 | K46: 0.005310297 | L46: 0.005343676 | M46: 0.005361319 | N46: 0.005429029 | O46: 0.00528121 | P46: 0.00534296 | R46: =PERCENTILE(G46:P46,0.9) -> 0.0055060861 | S46: =spmv_1!R$10/R46 -> 6.3623641 | T46: =S46/16 -> 0.39764775
A47: msdoor.mtx | B47: 7 | D47: 1262090 | E47: 0.437849 | G47: 0.006162643 | H47: 0.005767822 | I47: 0.005784988 | J47: 0.005754471 | K47: 0.005663395 | L47: 0.005694151 | M47: 0.005708456 | N47: 0.00578618 | O47: 0.005648851 | P47: 0.005678654 | R47: =PERCENTILE(G47:P47,0.9) -> 0.0058238263 | S47: =spmv_1!R$10/R47 -> 6.015242 | T47: =S47/16 -> 0.37595262
A48: msdoor.mtx | B48: 8 | D48: 1269447 | E48: 0.443366 | G48: 0.006116152 | H48: 0.005748272 | I48: 0.005771637 | J48: 0.005724669 | K48: 0.005566359 | L48: 0.005648851 | M48: 0.005681992 | N48: 0.005740881 | O48: 0.005631924 | P48: 0.005633354 | R48: =PERCENTILE(G48:P48,0.9) -> 0.0058060885 | S48: =spmv_1!R$10/R48 -> 6.0336187 | T48: =S48/16 -> 0.37710117
A49: msdoor.mtx | B49: 9 | D49: 1271596 | E49: 0.475991 | G49: 0.005788565 | H49: 0.005335569 | I49: 0.005298376 | J49: 0.005348444 | K49: 0.005200386 | L49: 0.005275726 | M49: 0.005311012 | N49: 0.005369186 | O49: 0.005226851 | P49: 0.005275249 | R49: =PERCENTILE(G49:P49,0.9) -> 0.0054111239 | S49: =spmv_1!R$10/R49 -> 6.47402 | T49: =S49/16 -> 0.40462625
A50: msdoor.mtx | B50: 10 | D50: 1269569 | E50: 0.456115 | G50: 0.005981445 | H50: 0.005537271 | I50: 0.005568266 | J50: 0.005557299 | K50: 0.005493641 | L50: 0.005498886 | M50: 0.005517244 | N50: 0.005582571 | O50: 0.005445242 | P50: 0.005486965 | R50: =PERCENTILE(G50:P50,0.9) -> 0.0056224584 | S50: =spmv_1!R$10/R50 -> 6.2306774 | T50: =S50/16 -> 0.38941734
...

Sheet spmv_2x8
A1: Matrix | B1: Rank | D1: Local NNZ | E1: GFLOPS | G1: Iter_0 | H1: Iter_1 | I1: Iter_2 | J1: Iter_3 | K1: Iter_4 | L1: Iter_5 | M1: Iter_6 | N1: Iter_7 | O1: Iter_8 | P1: Iter_9 | R1: 90 percentile | S1: Speedup | T1: Efficiency
A2: bmwcra_1.mtx | B2: 0 | D2: 666452 | E2: 0.571876 | G2: 0.004678249 | H2: 0.002353191 | I2: 0.002062798 | J2: 0.00211072 | K2: 0.001976252 | L2: 0.002060175 | M2: 0.001992226 | N2: 0.002053499 | O2: 0.001980066 | P2: 0.002040386 | R2: =PERCENTILE(G2:P2,0.9) -> 0.0025856968 | S2: =spmv_1!R$2/R2 -> 6.7383184 | T2: =S2/16 -> 0.4211449
A3: bmwcra_1.mtx | B3: 1 | D3: 667346 | E3: 0.515337 | G3: 0.006998301 | H3: 0.002379894 | I3: 0.002121687 | J3: 0.002151966 | K3: 0.002021074 | L3: 0.002095461 | M3: 0.002018213 | N3: 0.002072334 | O3: 0.001994848 | P3: 0.002045631 | R3: =PERCENTILE(G3:P3,0.9) -> 0.0028417347 | S3: =spmv_1!R$2/R3 -> 6.1312016 | T3: =S3/16 -> 0.3832001
A4: bmwcra_1.mtx | B4: 2 | D4: 665088 | E4: 0.578319 | G4: 0.003622293 | H4: 0.002352476 | I4: 0.002210617 | J4: 0.002180099 | K4: 0.002111197 | L4: 0.002115011 | M4: 0.002114058 | N4: 0.002105713 | O4: 0.002103806 | P4: 0.002085447 | R4: =PERCENTILE(G4:P4,0.9) -> 0.0024794577 | S4: =spmv_1!R$2/R4 -> 7.02704 | T4: =S4/16 -> 0.43919
A5: bmwcra_1.mtx | B5: 3 | D5: 663375 | E5: 0.60558 | G5: 0.003209114 | H5: 0.002287149 | I5: 0.002123594 | J5: 0.002118587 | K5: 0.002026558 | L5: 0.002058744 | M5: 0.002017021 | N5: 0.002021551 | O5: 0.002021551 | P5: 0.002024889 | R5: =PERCENTILE(G5:P5,0.9) -> 0.0023793455 | S5: =spmv_1!R$2/R5 -> 7.3227063 | T5: =S5/16 -> 0.45766915
A6: bmwcra_1.mtx | B6: 4 | D6: 662698 | E6: 0.605759 | G6: 0.00364852 | H6: 0.00225091 | I6: 0.0020926 | J6: 0.002036572 | K6: 0.001964331 | L6: 0.001987457 | M6: 0.00197649 | N6: 0.001979351 | O6: 0.001970053 | P6: 0.001973629 | R6: =PERCENTILE(G6:P6,0.9) -> 0.002390671 | S6: =spmv_1!R$2/R6 -> 7.288016 | T6: =S6/16 -> 0.455501
A7: bmwcra_1.mtx | B7: 5 | D7: 665594 | E7: 0.617217 | G7: 0.003391027 | H7: 0.002202511 | I7: 0.002055883 | J7: 0.002042294 | K7: 0.00197506 | L7: 0.001976252 | M7: 0.001963139 | N7: 0.001974106 | O7: 0.001999617 | P7: 0.001987696 | R7: =PERCENTILE(G7:P7,0.9) -> 0.0023213626 | S7: =spmv_1!R$2/R7 -> 7.5056126 | T7: =S7/16 -> 0.46910079
A8: bmwcra_1.mtx | B8: 6 | D8: 665712 | E8: 0.604274 | G8: 0.004482985 | H8: 0.002138615 | I8: 0.001986027 | J8: 0.00195241 | K8: 0.001884222 | L8: 0.001928806 | M8: 0.001914978 | N8: 0.001908064 | O8: 0.001915693 | P8: 0.001921654 | R8: =PERCENTILE(G8:P8,0.9) -> 0.002373052 | S8: =spmv_1!R$2/R8 -> 7.3421267 | T8: =S8/16 -> 0.45888292
A9: bmwcra_1.mtx | B9: 7 | D9: 666565 | E9: 0.671682 | G9: 0.002758265 | H9: 0.002070189 | I9: 0.001944065 | J9: 0.00191617 | K9: 0.001847506 | L9: 0.001879215 | M9: 0.001859665 | N9: 0.001844168 | O9: 0.001859665 | P9: 0.001868725 | R9: =PERCENTILE(G9:P9,0.9) -> 0.0021389966 | S9: =spmv_1!R$2/R9 -> 8.1455241 | T9: =S9/16 -> 0.50909526
A10: bmwcra_1.mtx | B10: 8 | D10: 663192 | E10: 0.528782 | G10: 0.003523111 | H10: 0.002571344 | I10: 0.002551079 | J10: 0.002466917 | K10: 0.002370596 | L10: 0.002309561 | M10: 0.002413988 | N10: 0.002338886 | O10: 0.002256393 | P10: 0.002281904 | R10: =PERCENTILE(G10:P10,0.9) -> 0.0026665207 | S10: =spmv_1!R$2/R10 -> 6.5340758 | T10: =S10/16 -> 0.40837974
A11: bmwcra_1.mtx | B11: 9 | D11: 664738 | E11: 0.538433 | G11: 0.003499985 | H11: 0.002536058 | I11: 0.00252986 | J11: 0.002428293 | K11: 0.002323866 | L11: 0.002266169 | M11: 0.002357006 | N11: 0.00229454 | O11: 0.002214193 | P11: 0.002241611 | R11: =PERCENTILE(G11:P11,0.9) -> 0.0026324507 | S11: =spmv_1!R$2/R11 -> 6.6186419 | T11: =S11/16 -> 0.41366512
A12: bmwcra_1.mtx | B12: 10 | D12: 664591 | E12: 0.624866 | G12: 0.003163338 | H12: 0.002377033 | I12: 0.002188206 | J12: 0.002065897 | K12: 0.001962662 | L12: 0.001893282 | M12: 0.001963377 | N12: 0.001872301 | O12: 0.001883745 | P12: 0.001901627 | R12: =PERCENTILE(G12:P12,0.9) -> 0.0024556635 | S12: =spmv_1!R$2/R12 -> 7.0951286 | T12: =S12/16 -> 0.44344554
A13: bmwcra_1.mtx | B13: 11 | D13: 667685 | E13: 0.559183 | G13: 0.003382683 | H13: 0.002465963 | I13: 0.002432823 | J13: 0.002359867 | K13: 0.002256393 | L13: 0.002187252 | M13: 0.002286434 | N13: 0.002203703 | O13: 0.002153635 | P13: 0.002151966 | R13: =PERCENTILE(G13:P13,0.9) -> 0.002557635 | S13: =spmv_1!R$2/R13 -> 6.8122498 | T13: =S13/16 -> 0.42576561
... A17: bmwcra_1.mtx | B17: 15 | D17: 665021 | E17: 0.747832 | G17: 0.002658129 | H17: 0.001827955 | I17: 0.001818419 | J17: 0.001682043 | K17: 0.001667023 | L17: 0.001661062 | M17: 0.001664639 | N17: 0.001608849 | O17: 0.001597881 | P17: 0.001599312 | R17: =PERCENTILE(G17:P17,0.9) -> 0.0019109724 | S17: =spmv_1!R$2/R17 -> 9.1174778 | T17: =S17/16 -> 0.56984236
A20: Matrix | B20: Rank | D20: Local NNZ | E20: GFLOPS | G20: Iter_0 | H20: Iter_1 | I20: Iter_2 | J20: Iter_3 | K20: Iter_4 | L20: Iter_5 | M20: Iter_6 | N20: Iter_7 | O20: Iter_8 | P20: Iter_9 | R20: 90 percentile | S20: Speedup | T20: Efficiency
A21: ML_Geer.mtx | B21: 0 | D21: 6930698 | E21: 0.537631 | G21: 0.026629448 | H21: 0.027374744 | I21: 0.027020693 | J21: 0.026025057 | K21: 0.02544117 | L21: 0.025626183 | M21: 0.024625301 | N21: 0.025496244 | O21: 0.025043249 | P21: 0.024541378 | R21: =PERCENTILE(G21:P21,0.9) -> 0.027056098 | S21: =spmv_1!R$6/R21 -> 6.2179923 | T21: =S21/16 -> 0.38862452
A22: ML_Geer.mtx | B22: 1 | D22: 6930722 | E22: 0.534968 | G22: 0.026901245 | H22: 0.027281523 | I22: 0.027101278 | J22: 0.026138783 | K22: 0.025616407 | L22: 0.025712252 | M22: 0.02482748 | N22: 0.025489807 | O22: 0.025339127 | P22: 0.024700165 | R22: =PERCENTILE(G22:P22,0.9) -> 0.027119303 | S22: =spmv_1!R$6/R22 -> 6.2035006 | T22: =S22/16 -> 0.38771879
A23: ML_Geer.mtx | B23: 2 | D23: 6929254 | E23: 0.532494 | G23: 0.026913643 | H23: 0.027362585 | I23: 0.027256012 | J23: 0.026221514 | K23: 0.025821447 | L23: 0.025673866 | M23: 0.024930239 | N23: 0.025813341 | O23: 0.025361538 | P23: 0.024902582 | R23: =PERCENTILE(G23:P23,0.9) -> 0.027266669 | S23: =spmv_1!R$6/R23 -> 6.1699729 | T23: =S23/16 -> 0.38562331
A24: ML_Geer.mtx | B24: 3 | D24: 6929236 | E24: 0.55171 | G24: 0.025847197 | H24: 0.026570082 | I24: 0.026399136 | J24: 0.025259018 | K24: 0.025104523 | L24: 0.024794102 | M24: 0.024228096 | N24: 0.024763823 | O24: 0.024196625 | P24: 0.02402854 | R24: =PERCENTILE(G24:P24,0.9) -> 0.026416231 | S24: =spmv_1!R$6/R24 -> 6.3686077 | T24: =S24/16 -> 0.39803798
A25: ML_Geer.mtx | B25: 4 | D25: 6928044 | E25: 0.568932 | G25: 0.025214911 | H25: 0.025974274 | I25: 0.025475979 | J25: 0.024556875 | K25: 0.024325132 | L25: 0.024059057 | M25: 0.023238182 | N25: 0.02402854 | O25: 0.0234375 | P25: 0.023235321 | R25: =PERCENTILE(G25:P25,0.9) -> 0.025525809 | S25: =spmv_1!R$6/R25 -> 6.5907652 | T25: =S25/16 -> 0.41192283
A26: ML_Geer.mtx | B26: 5 | D26: 6928026 | E26: 0.587641 | G26: 0.024461031 | H26: 0.024668694 | I26: 0.024715185 | J26: 0.023771524 | K26: 0.023467779 | L26: 0.023290396 | M26: 0.022686958 | N26: 0.023333788 | O26: 0.022830009 | P26: 0.022565842 | R26: =PERCENTILE(G26:P26,0.9) -> 0.024673343 | S26: =spmv_1!R$6/R26 -> 6.8184765 | T26: =S26/16 -> 0.42615478
A27: ML_Geer.mtx | B27: 6 | D27: 6929656 | E27: 0.582636 | G27: 0.025199175 | H27: 0.024124384 | I27: 0.023989201 | J27: 0.02304697 | K27: 0.023685217 | L27: 0.023454189 | M27: 0.023644447 | N27: 0.023436308 | O27: 0.023717403 | P27: 0.023575068 | R27: =PERCENTILE(G27:P27,0.9) -> 0.024231863 | S27: =spmv_1!R$6/R27 -> 6.9427023 | T27: =S27/16 -> 0.43391889
A28: ML_Geer.mtx | B28: 7 | D28: 6929668 | E28: 0.581194 | G28: 0.025618792 | H28: 0.022770405 | I28: 0.022955894 | J28: 0.022808313 | K28: 0.023834705 | L28: 0.024093151 | M28: 0.023860931 | N28: 0.023923159 | O28: 0.024603605 | P28: 0.023994207 | R28: =PERCENTILE(G28:P28,0.9) -> 0.024705124 | S28: =spmv_1!R$6/R28 -> 6.8097053 | T28: =S28/16 -> 0.42560658
A29: ML_Geer.mtx | B29: 8 | D29: 6931296 | E29: 0.42763 | G29: 0.042211533 | H29: 0.028882265 | I29: 0.030088186 | J29: 0.030667543 | K29: 0.032145023 | L29: 0.032002687 | M29: 0.031907797 | N29: 0.031786203 | O29: 0.032864809 | P29: 0.031616449 | R29: =PERCENTILE(G29:P29,0.9) -> 0.033799481 | S29: =spmv_1!R$6/R29 -> 4.9774317 | T29: =S29/16 -> 0.31108948
A30: ML_Geer.mtx | B30: 9 | D30: 6931306 | E30: 0.426584 | G30: 0.042117596 | H30: 0.029307842 | I30: 0.029947996 | J30: 0.030648708 | K30: 0.031876326 | L30: 0.031990051 | M30: 0.032262564 | N30: 0.031658411 | O30: 0.033245802 | P30: 0.031912327 | R30: =PERCENTILE(G30:P30,0.9) -> 0.034132981 | S30: =spmv_1!R$6/R30 -> 4.9287992 | T30: =S30/16 -> 0.30804995
A31: ML_Geer.mtx | B31: 10 | D31: 6930758 | E31: 0.378912 | G31: 0.042617798 | H31: 0.036623001 | I31: 0.036302328 | J31: 0.035794735 | K31: 0.035712004 | L31: 0.03583312 | M31: 0.035692692 | N31: 0.035370588 | O31: 0.035995245 | P31: 0.035882473 | R31: =PERCENTILE(G31:P31,0.9) -> 0.037222481 | S31: =spmv_1!R$6/R31 -> 4.5197044 | T31: =S31/16 -> 0.28248153
A32: ML_Geer.mtx | B32: 11 | D32: 6930730 | E32: 0.433604 | G32: 0.041167259 | H32: 0.031187534 | I32: 0.031903744 | J32: 0.031285048 | K32: 0.030954599 | L32: 0.031168699 | M32: 0.030559063 | N32: 0.030790329 | O32: 0.030218363 | P32: 0.030445576 | R32: =PERCENTILE(G32:P32,0.9) -> 0.032830096 | S32: =spmv_1!R$6/R32 -> 5.1244021 | T32: =S32/16 -> 0.32027513
... A36: ML_Geer.mtx | B36: 15 | D36: 6929668 | E36: 0.418839 | G36: 0.042138338 | H36: 0.032252312 | I36: 0.032766104 | J36: 0.031924248 | K36: 0.03219676 | L36: 0.032335997 | M36: 0.031894684 | N36: 0.03218627 | O36: 0.032075882 | P36: 0.031128645 | R36: =PERCENTILE(G36:P36,0.9) -> 0.033703327 | S36: =spmv_1!R$6/R36 -> 4.9916321 | T36: =S36/16 -> 0.31197701
A39: Matrix | B39: Rank | D39: Local NNZ | E39: GFLOPS | G39: Iter_0 | H39: Iter_1 | I39: Iter_2 | J39: Iter_3 | K39: Iter_4 | L39: Iter_5 | M39: Iter_6 | N39: Iter_7 | O39: Iter_8 | P39: Iter_9 | R39: 90 percentile | S39: Speedup | T39: Efficiency
A40: msdoor.mtx | B40: 0 | D40: 1267995 | E40: 0.328518 | G40: 0.007842541 | H40: 0.007570982 | I40: 0.007877827 | J40: 0.007811546 | K40: 0.007519007 | L40: 0.007532597 | M40: 0.007547855 | N40: 0.007601261 | O40: 0.007989883 | P40: 0.00790143 | R40: =PERCENTILE(G40:P40,0.9) -> 0.0079102753 | S40: =spmv_1!R$10/R40 -> 4.4286353 | T40: =S40/16 -> 0.27678971
A41: msdoor.mtx | B41: 1 | D41: 1268949 | E41: 0.324325 | G41: 0.007976532 | H41: 0.007671118 | I41: 0.007972002 | J41: 0.007926464 | K41: 0.007614851 | L41: 0.007643461 | M41: 0.007653475 | N41: 0.007702589 | O41: 0.008086205 | P41: 0.008004904 | R41: =PERCENTILE(G41:P41,0.9) -> 0.0080130341 | S41: =spmv_1!R$10/R41 -> 4.3718427 | T41: =S41/16 -> 0.27324017
A42: msdoor.mtx | B42: 2 | D42: 1266254 | E42: 0.351829 | G42: 0.007445574 | H42: 0.007060051 | I42: 0.007079601 | J42: 0.007294416 | K42: 0.007008791 | L42: 0.006994009 | M42: 0.007045269 | N42: 0.007154942 | O42: 0.007479429 | P42: 0.007419109 | R42: =PERCENTILE(G42:P42,0.9) -> 0.0074489595 | S42: =spmv_1!R$10/R42 -> 4.7029017 | T42: =S42/16 -> 0.29393136
A43: msdoor.mtx | B43: 3 | D43: 1268739 | E43: 0.353074 | G43: 0.007438421 | H43: 0.007071495 | I43: 0.007072926 | J43: 0.007284403 | K43: 0.006974936 | L43: 0.00697732 | M43: 0.007045507 | N43: 0.007124901 | O43: 0.007468224 | P43: 0.007410049 | R43: =PERCENTILE(G43:P43,0.9) -> 0.0074414013 | S43: =spmv_1!R$10/R43 -> 4.7076784 | T43: =S43/16 -> 0.2942299
A44: msdoor.mtx | B44: 4 | D44: 1260291 | E44: 0.342207 | G44: 0.007757664 | H44: 0.007215261 | I44: 0.007271051 | J44: 0.007442236 | K44: 0.007144451 | L44: 0.007163048 | M44: 0.007203817 | N44: 0.007271051 | O44: 0.007620811 | P44: 0.007567167 | R44: =PERCENTILE(G44:P44,0.9) -> 0.0076344963 | S44: =spmv_1!R$10/R44 -> 4.5886098 | T44: =S44/16 -> 0.28678811
A45: msdoor.mtx | B45: 5 | D45: 1261447 | E45: 0.324358 | G45: 0.008393526 | H45: 0.007646799 | I45: 0.007538319 | J45: 0.007713318 | K45: 0.007674456 | L45: 0.007754326 | M45: 0.007746696 | N45: 0.007690907 | O45: 0.007577658 | P45: 0.008045197 | R45: =PERCENTILE(G45:P45,0.9) -> 0.0080800299 | S45: =spmv_1!R$10/R45 -> 4.3355934 | T45: =S45/16 -> 0.27097459
A46: msdoor.mtx | B46: 6 | D46: 1260486 | E46: 0.317711 | G46: 0.008497477 | H46: 0.007793665 | I46: 0.0078125 | J46: 0.007814646 | K46: 0.007760286 | L46: 0.007783413 | M46: 0.007971764 | N46: 0.007946968 | O46: 0.007793903 | P46: 0.008173227 | R46: =PERCENTILE(G46:P46,0.9) -> 0.008205652 | S46: =spmv_1!R$10/R46 -> 4.2692189 | T46: =S46/16 -> 0.26682618
A47: msdoor.mtx | B47: 7 | D47: 1262090 | E47: 0.290457 | G47: 0.009217262 | H47: 0.008417606 | I47: 0.008558989 | J47: 0.008524179 | K47: 0.008583784 | L47: 0.008620977 | M47: 0.008667707 | N47: 0.008655787 | O47: 0.008617163 | P47: 0.009040356 | R47: =PERCENTILE(G47:P47,0.9) -> 0.0090580466 | S47: =spmv_1!R$10/R47 -> 3.8674701 | T47: =S47/16 -> 0.24171688
A48: msdoor.mtx | B48: 8 | D48: 1269447 | E48: 0.256479 | G48: 0.010501623 | H48: 0.009883165 | I48: 0.009721756 | J48: 0.009915829 | K48: 0.009854078 | L48: 0.009629011 | M48: 0.009865522 | N48: 0.009943008 | O48: 0.009487629 | P48: 0.01018858 | R48: =PERCENTILE(G48:P48,0.9) -> 0.010219884 | S48: =spmv_1!R$10/R48 -> 3.4278005 | T48: =S48/16 -> 0.21423753
A49: msdoor.mtx | B49: 9 | D49: 1271596 | E49: 0.305861 | G49: 0.014813185 | H49: 0.007547379 | I49: 0.007560492 | J49: 0.007576942 | K49: 0.007579088 | L49: 0.007461548 | M49: 0.00758791 | N49: 0.007590532 | O49: 0.00749445 | P49: 0.007937193 | R49: =PERCENTILE(G49:P49,0.9) -> 0.0086247922 | S49: =spmv_1!R$10/R49 -> 4.0617471 | T49: =S49/16 -> 0.25385919
A50: msdoor.mtx | B50: 10 | D50: 1269569 | E50: 0.266017 | G50: 0.010242462 | H50: 0.009700298 | I50: 0.009432554 | J50: 0.009599209 | K50: 0.009480953 | L50: 0.009261608 | M50: 0.009420633 | N50: 0.009538651 | O50: 0.009068966 | P50: 0.009704828 | R50: =PERCENTILE(G50:P50,0.9) -> 0.0097585914 | S50: =spmv_1!R$10/R50 -> 3.5898341 | T50: =S50/16 -> 0.22436463
...

Sheet spmv_2x16
A1: Matrix | B1: Rank | D1: Local NNZ | E1: GFLOPS | G1: Iter_0 | H1: Iter_1 | I1: Iter_2 | J1: Iter_3 | K1: Iter_4 | L1: Iter_5 | M1: Iter_6 | N1: Iter_7 | O1: Iter_8 | P1: Iter_9 | R1: 90 percentile | S1: Speedup | T1: Efficiency
A2: bmwcra_1.mtx | B2: 0 | D2: 334767 | E2: 0.3082 | G2: 0.003142118 | H2: 0.002468586 | I2: 0.00225687 | J2: 0.002562523 | K2: 0.002287388 | L2: 0.001948595 | M2: 0.001868486 | N2: 0.001846552 | O2: 0.00170064 | P2: 0.001642227 | R2: =PERCENTILE(G2:P2,0.9) -> 0.0026204825 | S2: =spmv_1!R$2/R2 -> 6.6488704 | T2: =S2/32 -> 0.2077772
A3: bmwcra_1.mtx | B3: 1 | D3: 335777 | E3: 0.309885 | G3: 0.003232956 | H3: 0.002453804 | I3: 0.002284288 | J3: 0.002555132 | K3: 0.002288342 | L3: 0.001928329 | M3: 0.001856565 | N3: 0.001803875 | O3: 0.001657248 | P3: 0.001610518 | R3: =PERCENTILE(G3:P3,0.9) -> 0.0026229144 | S3: =spmv_1!R$2/R3 -> 6.6427057 | T3: =S3/32 -> 0.20758455
A4: bmwcra_1.mtx | B4: 2 | D4: 334221 | E4: 0.305119 | G4: 0.003208876 | H4: 0.002468109 | I4: 0.002327681 | J4: 0.002563715 | K4: 0.00229454 | L4: 0.001962662 | M4: 0.001888037 | N4: 0.001859903 | O4: 0.001700401 | P4: 0.001633644 | R4: =PERCENTILE(G4:P4,0.9) -> 0.0026282311 | S4: =spmv_1!R$2/R4 -> 6.629268 | T4: =S4/32 -> 0.20716463
A5: bmwcra_1.mtx | B5: 3 | D5: 332836 | E5: 0.309185 | G5: 0.003132343 | H5: 0.002407551 | I5: 0.002344847 | J5: 0.002476931 | K5: 0.002249718 | L5: 0.001920223 | M5: 0.001866579 | N5: 0.001827002 | O5: 0.001681805 | P5: 0.001622915 | R5: =PERCENTILE(G5:P5,0.9) -> 0.0025424722 | S5: =spmv_1!R$2/R5 -> 6.8528767 | T5: =S5/32 -> 0.2141524
A6: bmwcra_1.mtx | B6: 4 | D6: 331435 | E6: 0.311743 | G6: 0.003157854 | H6: 0.00236392 | I6: 0.002364635 | J6: 0.002455235 | K6: 0.002170324 | L6: 0.001869917 | M6: 0.001818895 | N6: 0.001765966 | O6: 0.001638889 | P6: 0.001657724 | R6: =PERCENTILE(G6:P6,0.9) -> 0.0025254969 | S6: =spmv_1!R$2/R6 -> 6.8989387 | T6: =S6/32 -> 0.21559184
A7: bmwcra_1.mtx | B7: 5 | D7: 331788 | E7: 0.312692 | G7: 0.003153801 | H7: 0.002295971 | I7: 0.00239563 | J7: 0.002475977 | K7: 0.002182961 | L7: 0.001874447 | M7: 0.00178051 | N7: 0.001720428 | O7: 0.001674891 | P7: 0.001666784 | R7: =PERCENTILE(G7:P7,0.9) -> 0.0025437594 | S7: =spmv_1!R$2/R7 -> 6.8494089 | T7: =S7/32 -> 0.21404403
A8: bmwcra_1.mtx | B8: 6 | D8: 331215 | E8: 0.317455 | G8: 0.003110886 | H8: 0.002251863 | I8: 0.002389669 | J8: 0.002447367 | K8: 0.002167225 | L8: 0.001829147 | M8: 0.001746655 | N8: 0.001678944 | O8: 0.001637459 | P8: 0.001607656 | R8: =PERCENTILE(G8:P8,0.9) -> 0.0025137189 | S8: =spmv_1!R$2/R8 -> 6.9312636 | T8: =S8/32 -> 0.21660199
A9: bmwcra_1.mtx | B9: 7 | D9: 331506 | E9: 0.32393 | G9: 0.003127813 | H9: 0.002154827 | I9: 0.002283573 | J9: 0.002417088 | K9: 0.00209713 | L9: 0.00179863 | M9: 0.001713753 | N9: 0.001655817 | O9: 0.001613379 | P9: 0.001605749 | R9: =PERCENTILE(G9:P9,0.9) -> 0.0024881605 | S9: =spmv_1!R$2/R9 -> 7.0024616 | T9: =S9/32 -> 0.21882693
A10: bmwcra_1.mtx | B10: 8 | D10: 330876 | E10: 0.326705 | G10: 0.003057241 | H10: 0.002120256 | I10: 0.002291918 | J10: 0.002417088 | K10: 0.002101183 | L10: 0.001801729 | M10: 0.00169301 | N10: 0.001636028 | O10: 0.001580238 | P10: 0.001556635 | R10: =PERCENTILE(G10:P10,0.9) -> 0.0024811033 | S10: =spmv_1!R$2/R10 -> 7.0223793 | T10: =S10/32 -> 0.21944935
