Workbook

Sheet overall
A1: SEQUENTIAL
A2: matrice | B2: metrica | C2: Test 1 | D2: Test 2 | E2: Test 3 | F2: Test 4 | G2: Test 5 | H2: Test 6 | I2: Test 7 | J2: Test 8 | K2: Test 9 | L2: Test 10 | N2: 90 percentile
A3: ML_Geer.mtx | B3: CPU | C3: 330 | D3: 330 | E3: 310 | F3: 280 | G3: 280 | H3: 290 | I3: 290 | J3: 280 | K3: 290 | L3: 290 | N3: =PERCENTILE(C3:L3,0.9) -> 330
B4: REAL | C4: 337.897 | D4: 334.885 | E4: 315.053 | F4: 281.009 | G4: 285.559 | H4: 293.576 | I4: 296.252 | J4: 287.828 | K4: 289.84 | L4: 287.972 | N4: =PERCENTILE(C4:L4,0.9) -> 335.1862
A5: PFlow_742.mtx | B5: CPU | C5: 110 | D5: 110 | E5: 100 | F5: 100 | G5: 100 | H5: 100 | I5: 90 | J5: 90 | K5: 90 | L5: 90 | N5: =PERCENTILE(C5:L5,0.9) -> 110
B6: REAL | C6: 103.778 | D6: 107.721 | E6: 91.308 | F6: 93.819 | G6: 91.619 | H6: 94.419 | I6: 90.331 | J6: 92.612 | K6: 91.259 | L6: 93.925 | N6: =PERCENTILE(C6:L6,0.9) -> 104.1723
A7: bmwcra_1.mtx | B7: CPU | C7: 30 | D7: 30 | E7: 30 | F7: 30 | G7: 30 | H7: 30 | I7: 30 | J7: 30 | K7: 30 | L7: 20 | N7: =PERCENTILE(C7:L7,0.9) -> 30
B8: REAL | C8: 32.572 | D8: 31.383 | E8: 31.859 | F8: 29.893 | G8: 28.124 | H8: 28.328 | I8: 28.366 | J8: 28.933 | K8: 28.085 | L8: 27.885 | N8: =PERCENTILE(C8:L8,0.9) -> 31.9303
A9: msdoor.mtx | B9: CPU | C9: 60 | D9: 60 | E9: 60 | F9: 50 | G9: 40 | H9: 60 | I9: 50 | J9: 50 | K9: 50 | L9: 50 | N9: =PERCENTILE(C9:L9,0.9) -> 60
B10: REAL | C10: 109.421 | D10: 59.474 | E10: 58.849 | F10: 50.369 | G10: 49.794 | H10: 51.653 | I10: 52.727 | J10: 50.733 | K10: 51.269 | L10: 50.823 | N10: =PERCENTILE(C10:L10,0.9) -> 64.4687
A11: nlpkkt240.mtx | B11: CPU | C11: 1840 | D11: 1880 | E11: 1690 | F11: 1840 | G11: 1620 | H11: 1800 | I11: 1770 | J11: 1660 | K11: 1650 | L11: 1670 | N11: =PERCENTILE(C11:L11,0.9) -> 1844
B12: REAL | C12: 1844.783 | D12: 1883.559 | E12: 1695.884 | F12: 1844.39 | G12: 1630.52 | H12: 1801.218 | I12: 1775.783 | J12: 1658.855 | K12: 1653.927 | L12: 1672.572 | N12: =PERCENTILE(C12:L12,0.9) -> 1848.6606
T16: CHUNK_SIZE = AUTO (1) | AM16: CHUNK_SIZE = AUTO (iterazioni rimaste/#theads)
A18: STATIC – 4 | T18: DYNAMIC – 4 | AM18: GUIDED – 4
A19: matrice | B19: metrica | C19: Test 1 | D19: Test 2 | E19: Test 3 | F19: Test 4 | G19: Test 5 | H19: Test 6 | I19: Test 7 | J19: Test 8 | K19: Test 9 | L19: Test 10 | N19: 90 percentile | O19: Speedup | P19: Efficiency | T19: matrice | U19: metrica | V19: Test 1 | W19: Test 2 | X19: Test 3 | Y19: Test 4 | Z19: Test 5 | AA19: Test 6 | AB19: Test 7 | AC19: Test 8 | AD19: Test 9 | AE19: Test 10 | AG19: 90 percentile | AH19: Speedup | AI19: Efficiency | AM19: matrice | AN19: metrica | AO19: Test 1 | AP19: Test 2 | AQ19: Test 3 | AR19: Test 4 | AS19: Test 5 | AT19: Test 6 | AU19: Test 7 | AV19: Test 8 | AW19: Test 9 | AX19: Test 10 | AZ19: 90 percentile | BA19: Speedup | BB19: Efficiency
A20: ML_Geer.mtx | B20: CPU | C20: 160 | D20: 170 | E20: 160 | F20: 150 | G20: 180 | H20: 2040 | I20: 160 | J20: 160 | K20: 160 | L20: 150 | N20: =PERCENTILE(C20:L20,0.9) -> 366 | T20: ML_Geer.mtx | U20: CPU | V20: 1460 | W20: 1450 | X20: 1450 | Y20: 1380 | Z20: 1440 | AA20: 1710 | AB20: 1460 | AC20: 1220 | AD20: 1310 | AE20: 1120 | AG20: =PERCENTILE(V20:AE20,0.9) -> 1485 | AM20: ML_Geer.mtx | AN20: CPU | AO20: 1010 | AP20: 440 | AQ20: 400 | AR20: 500 | AS20: 510 | AT20: 690 | AU20: 460 | AV20: 800 | AW20: 530 | AX20: 2570 | AZ20: =PERCENTILE(AO20:AX20,0.9) -> 1166
B21: REAL | C21: 41.969 | D21: 41.731 | E21: 41.918 | F21: 37.43 | G21: 48.763 | H21: 782.105 | I21: 42.062 | J21: 41.185 | K21: 41.278 | L21: 40.574 | N21: =PERCENTILE(C21:L21,0.9) -> 122.0972 | O21: =N4/N21 -> 2.7452407 | P21: =O21/4 -> 0.68631017 | U21: REAL | V21: 365.342 | W21: 364.068 | X21: 365.226 | Y21: 346.562 | Z21: 362.534 | AA21: 428.369 | AB21: 366.158 | AC21: 307.163 | AD21: 336.303 | AE21: 280.71 | AG21: =PERCENTILE(V21:AE21,0.9) -> 372.3791 | AH21: =N4/AG21 -> 0.90012087 | AI21: =AH21/4 -> 0.22503022 | AN21: REAL | AO21: 379.34 | AP21: 208.954 | AQ21: 195.569 | AR21: 238.803 | AS21: 212.555 | AT21: 206.07 | AU21: 233.166 | AV21: 400.443 | AW21: 220.402 | AX21: 727.669 | AZ21: =PERCENTILE(AO21:AX21,0.9) -> 433.1656 | BA21: =N4/AZ21 -> 0.77380614 | BB21: =BA21/4 -> 0.19345153
A22: PFlow_742.mtx | B22: CPU | C22: 70 | D22: 70 | E22: 70 | F22: 60 | G22: 110 | H22: 70 | I22: 50 | J22: 60 | K22: 60 | L22: 60 | N22: =PERCENTILE(C22:L22,0.9) -> 74 | T22: PFlow_742.mtx | U22: CPU | V22: 650 | W22: 630 | X22: 650 | Y22: 500 | Z22: 650 | AA22: 640 | AB22: 490 | AC22: 480 | AD22: 1370 | AE22: 480 | AG22: =PERCENTILE(V22:AE22,0.9) -> 722 | AM22: PFlow_742.mtx | AN22: CPU | AO22: 170 | AP22: 260 | AQ22: 170 | AR22: 160 | AS22: 200 | AT22: 210 | AU22: 220 | AV22: 160 | AW22: 520 | AX22: 660 | AZ22: =PERCENTILE(AO22:AX22,0.9) -> 534
B23: REAL | C23: 17.16 | D23: 17.433 | E23: 17.494 | F23: 14.029 | G23: 34.694 | H23: 17.442 | I23: 13.808 | J23: 15.99 | K23: 16.954 | L23: 15.945 | N23: =PERCENTILE(C23:L23,0.9) -> 19.214 | O23: =N6/N23 -> 5.4216873 | P23: =O23/4 -> 1.3554218 | U23: REAL | V23: 161.398 | W23: 159.687 | X23: 163.299 | Y23: 124.532 | Z23: 162.618 | AA23: 160.575 | AB23: 120.616 | AC23: 121.187 | AD23: 401.593 | AE23: 121.325 | AG23: =PERCENTILE(V23:AE23,0.9) -> 187.1284 | AH23: =N6/AG23 -> 0.55668888 | AI23: =AH23/4 -> 0.13917222 | AN23: REAL | AO23: 81.977 | AP23: 80.517 | AQ23: 90.874 | AR23: 84.765 | AS23: 77.15 | AT23: 82.719 | AU23: 102.134 | AV23: 80.363 | AW23: 128.259 | AX23: 165.009 | AZ23: =PERCENTILE(AO23:AX23,0.9) -> 131.934 | BA23: =N6/AZ23 -> 0.78957888 | BB23: =BA23/4 -> 0.19739472
A24: bmwcra_1.mtx | B24: CPU | C24: 20 | D24: 100 | E24: 20 | F24: 20 | G24: 20 | H24: 90 | I24: 30 | J24: 20 | K24: 20 | L24: 20 | N24: =PERCENTILE(C24:L24,0.9) -> 91 | T24: bmwcra_1.mtx | U24: CPU | V24: 140 | W24: 140 | X24: 140 | Y24: 150 | Z24: 150 | AA24: 170 | AB24: 150 | AC24: 110 | AD24: 110 | AE24: 110 | AG24: =PERCENTILE(V24:AE24,0.9) -> 152 | AM24: bmwcra_1.mtx | AN24: CPU | AO24: 70 | AP24: 60 | AQ24: 60 | AR24: 60 | AS24: 50 | AT24: 50 | AU24: 60 | AV24: 60 | AW24: 60 | AX24: 110 | AZ24: =PERCENTILE(AO24:AX24,0.9) -> 74
B25: REAL | C25: 4.571 | D25: 44.046 | E25: 5.123 | F25: 5.124 | G25: 5.197 | H25: 47.409 | I25: 9.815 | J25: 5.545 | K25: 4.364 | L25: 4.625 | N25: =PERCENTILE(C25:L25,0.9) -> 44.3823 | O25: =N8/N25 -> 0.7194377 | P25: =O25/4 -> 0.17985943 | U25: REAL | V25: 36.094 | W25: 35.925 | X25: 36.208 | Y25: 36.347 | Z25: 36.184 | AA25: 42.437 | AB25: 36.572 | AC25: 27.661 | AD25: 27.306 | AE25: 27.401 | AG25: =PERCENTILE(V25:AE25,0.9) -> 37.1585 | AH25: =N8/AG25 -> 0.85930003 | AI25: =AH25/4 -> 0.21482501 | AN25: REAL | AO25: 34.565 | AP25: 34.723 | AQ25: 27.891 | AR25: 35.471 | AS25: 25.394 | AT25: 27.817 | AU25: 34.534 | AV25: 27.582 | AW25: 27.898 | AX25: 28.556 | AZ25: =PERCENTILE(AO25:AX25,0.9) -> 34.7978 | BA25: =N8/AZ25 -> 0.91759537 | BB25: =BA25/4 -> 0.22939884
A26: msdoor.mtx | B26: CPU | C26: 30 | D26: 40 | E26: 40 | F26: 30 | G26: 40 | H26: 40 | I26: 50 | J26: 30 | K26: 30 | L26: 30 | N26: =PERCENTILE(C26:L26,0.9) -> 41 | T26: msdoor.mtx | U26: CPU | V26: 770 | W26: 620 | X26: 270 | Y26: 350 | Z26: 360 | AA26: 370 | AB26: 360 | AC26: 270 | AD26: 260 | AE26: 270 | AG26: =PERCENTILE(V26:AE26,0.9) -> 635 | AM26: msdoor.mtx | AN26: CPU | AO26: 210 | AP26: 130 | AQ26: 120 | AR26: 130 | AS26: 100 | AT26: 160 | AU26: 110 | AV26: 120 | AW26: 110 | AX26: 290 | AZ26: =PERCENTILE(AO26:AX26,0.9) -> 218
B27: REAL | C27: 8.59 | D27: 8.468 | E27: 10.105 | F27: 7.56 | G27: 10.099 | H27: 10.3 | I27: 9.78 | J27: 9.54 | K27: 9.443 | L27: 8.446 | N27: =PERCENTILE(C27:L27,0.9) -> 10.1245 | O27: =N10/N27 -> 6.3675935 | P27: =O27/4 -> 1.5918984 | U27: REAL | V27: 219.52 | W27: 170.692 | X27: 70.273 | Y27: 86.188 | Z27: 90.421 | AA27: 92.326 | AB27: 91.573 | AC27: 67.044 | AD27: 67.72 | AE27: 68.534 | AG27: =PERCENTILE(V27:AE27,0.9) -> 175.5748 | AH27: =N10/AG27 -> 0.36718652 | AI27: =AH27/4 -> 0.09179663 | AN27: REAL | AO27: 94.217 | AP27: 51.032 | AQ27: 60.917 | AR27: 54.348 | AS27: 50.037 | AT27: 71.977 | AU27: 61.117 | AV27: 62.411 | AW27: 60.923 | AX27: 73.257 | AZ27: =PERCENTILE(AO27:AX27,0.9) -> 75.353 | BA27: =N10/AZ27 -> 0.85555585 | BB27: =BA27/4 -> 0.21388896
A28: nlpkkt240.mtx | B28: CPU | C28: 5260 | D28: 1250 | E28: 5790 | F28: 3730 | G28: 2430 | H28: 5000 | I28: 1050 | J28: 8500 | K28: 1150 | L28: 1050 | N28: =PERCENTILE(C28:L28,0.9) -> 6061 | T28: nlpkkt240.mtx | U28: CPU | V28: 21260 | W28: 35350 | X28: 57500 | Y28: 68140 | Z28: 20580 | AA28: 38870 | AB28: 21770 | AC28: 45230 | AD28: 59580 | AE28: 50020 | AG28: =PERCENTILE(V28:AE28,0.9) -> 60436 | AM28: nlpkkt240.mtx | AN28: CPU | AO28: 34630 | AP28: 16220 | AQ28: 15640 | AR28: 15880 | AS28: 15640 | AT28: 8550 | AU28: 26660 | AV28: 8280 | AW28: 31470 | AX28: 52370 | AZ28: =PERCENTILE(AO28:AX28,0.9) -> 36404
B29: REAL | C29: 1873.344 | D29: 345.6 | E29: 2491.296 | F29: 1234.578 | G29: 832.239 | H29: 2186.588 | I29: 292.841 | J29: 3530.571 | K29: 324.268 | L29: 288.956 | N29: =PERCENTILE(C29:L29,0.9) -> 2595.2235 | O29: =N12/N29 -> 0.71233194 | P29: =O29/4 -> 0.17808299 | U29: REAL | V29: 6002.818 | W29: 10307.937 | X29: 16757.794 | Y29: 19599.747 | Z29: 5165.61 | AA29: 11407.926 | AB29: 6056.375 | AC29: 12704.355 | AD29: 17251.298 | AE29: 13983.424 | AG29: =PERCENTILE(V29:AE29,0.9) -> 17486.143 | AH29: =N12/AG29 -> 0.10572146 | AI29: =AH29/4 -> 0.026430366 | AN29: REAL | AO29: 12423.998 | AP29: 5023.034 | AQ29: 4328.091 | AR29: 4056.046 | AS29: 4203.333 | AT29: 2208.453 | AU29: 8329.773 | AV29: 2209.656 | AW29: 8873.681 | AX29: 15184.945 | AZ29: =PERCENTILE(AO29:AX29,0.9) -> 12700.093 | BA29: =N12/AZ29 -> 0.14556276 | BB29: =BA29/4 -> 0.036390691
A33: STATIC – 8 | T33: DYNAMIC – 8 | AM33: GUIDED – 8
A34: matrice | B34: metrica | C34: Test 1 | D34: Test 2 | E34: Test 3 | F34: Test 4 | G34: Test 5 | H34: Test 6 | I34: Test 7 | J34: Test 8 | K34: Test 9 | L34: Test 10 | N34: 90 percentile | O34: Speedup | P34: Efficiency | T34: matrice | U34: metrica | V34: Test 1 | W34: Test 2 | X34: Test 3 | Y34: Test 4 | Z34: Test 5 | AA34: Test 6 | AB34: Test 7 | AC34: Test 8 | AD34: Test 9 | AE34: Test 10 | AG34: 90 percentile | AH34: Speedup | AI34: Efficiency | AM34: matrice | AN34: metrica | AO34: Test 1 | AP34: Test 2 | AQ34: Test 3 | AR34: Test 4 | AS34: Test 5 | AT34: Test 6 | AU34: Test 7 | AV34: Test 8 | AW34: Test 9 | AX34: Test 10 | AZ34: 90 percentile | BA34: Speedup | BB34: Efficiency
A35: ML_Geer.mtx | B35: CPU | C35: 500 | D35: 500 | E35: 500 | F35: 510 | G35: 490 | H35: 500 | I35: 490 | J35: 500 | K35: 500 | L35: 500 | N35: =PERCENTILE(C35:L35,0.9) -> 501 | T35: ML_Geer.mtx | U35: CPU | V35: 2140 | W35: 2280 | X35: 2210 | Y35: 3460 | Z35: 2220 | AA35: 2290 | AB35: 2270 | AC35: 2260 | AD35: 2230 | AE35: 2240 | AG35: =PERCENTILE(V35:AE35,0.9) -> 2407 | AM35: ML_Geer.mtx | AN35: CPU | AO35: 2080 | AP35: 1940 | AQ35: 850 | AR35: 1560 | AS35: 1190 | AT35: 930 | AU35: 1320 | AV35: 1210 | AW35: 1230 | AX35: 2210 | AZ35: =PERCENTILE(AO35:AX35,0.9) -> 2093
B36: REAL | C36: 62.336 | D36: 62.127 | E36: 62.003 | F36: 62.127 | G36: 62.452 | H36: 62.316 | I36: 61.911 | J36: 61.912 | K36: 63.208 | L36: 62.443 | N36: =PERCENTILE(C36:L36,0.9) -> 62.5276 | O36: =N4/N36 -> 5.360612 | P36: =O36/8 -> 0.67007649 | U36: REAL | V36: 268.887 | W36: 285.317 | X36: 277.165 | Y36: 472.389 | Z36: 279.299 | AA36: 287.782 | AB36: 284.56 | AC36: 283.272 | AD36: 279.935 | AE36: 281.369 | AG36: =PERCENTILE(V36:AE36,0.9) -> 306.2427 | AH36: =N4/AG36 -> 1.0945116 | AI36: =AH36/8 -> 0.13681396 | AN36: REAL | AO36: 518.591 | AP36: 359.484 | AQ36: 208.164 | AR36: 315.3 | AS36: 249.867 | AT36: 222.34 | AU36: 250.995 | AV36: 274.293 | AW36: 268.533 | AX36: 277.032 | AZ36: =PERCENTILE(AO36:AX36,0.9) -> 375.3947 | BA36: =N4/AZ36 -> 0.89289007 | BB36: =BA36/8 -> 0.11161126
A37: PFlow_742.mtx | B37: CPU | C37: 170 | D37: 160 | E37: 180 | F37: 180 | G37: 180 | H37: 180 | I37: 170 | J37: 180 | K37: 190 | L37: 180 | N37: =PERCENTILE(C37:L37,0.9) -> 181 | T37: PFlow_742.mtx | U37: CPU | V37: 980 | W37: 1010 | X37: 1150 | Y37: 1080 | Z37: 1010 | AA37: 1030 | AB37: 990 | AC37: 1000 | AD37: 1040 | AE37: 1010 | AG37: =PERCENTILE(V37:AE37,0.9) -> 1087 | AM37: PFlow_742.mtx | AN37: CPU | AO37: 430 | AP37: 560 | AQ37: 440 | AR37: 640 | AS37: 590 | AT37: 750 | AU37: 880 | AV37: 640 | AW37: 990 | AX37: 990 | AZ37: =PERCENTILE(AO37:AX37,0.9) -> 990
B38: REAL | C38: 22.201 | D38: 21.052 | E38: 22.158 | F38: 22.283 | G38: 22.343 | H38: 22.216 | I38: 22.273 | J38: 22.185 | K38: 22.193 | L38: 23.223 | N38: =PERCENTILE(C38:L38,0.9) -> 22.431 | O38: =N6/N38 -> 4.644122 | P38: =O38/8 -> 0.58051525 | U38: REAL | V38: 123.017 | W38: 126.703 | X38: 231.395 | Y38: 209.109 | Z38: 125.663 | AA38: 129.601 | AB38: 124.017 | AC38: 125.809 | AD38: 130.269 | AE38: 126.311 | AG38: =PERCENTILE(V38:AE38,0.9) -> 211.3376 | AH38: =N6/AG38 -> 0.49291891 | AI38: =AH38/8 -> 0.061614864 | AN38: REAL | AO38: 99.202 | AP38: 110.803 | AQ38: 104.959 | AR38: 119.442 | AS38: 113.134 | AT38: 127.368 | AU38: 124.971 | AV38: 156.529 | AW38: 123.229 | AX38: 124.838 | AZ38: =PERCENTILE(AO38:AX38,0.9) -> 130.2841 | BA38: =N6/AZ38 -> 0.799578 | BB38: =BA38/8 -> 0.09994725
A39: bmwcra_1.mtx | B39: CPU | C39: 50 | D39: 40 | E39: 50 | F39: 50 | G39: 40 | H39: 50 | I39: 50 | J39: 50 | K39: 50 | L39: 50 | N39: =PERCENTILE(C39:L39,0.9) -> 50 | T39: bmwcra_1.mtx | U39: CPU | V39: 220 | W39: 220 | X39: 220 | Y39: 270 | Z39: 350 | AA39: 220 | AB39: 220 | AC39: 230 | AD39: 220 | AE39: 220 | AG39: =PERCENTILE(V39:AE39,0.9) -> 278 | AM39: bmwcra_1.mtx | AN39: CPU | AO39: 150 | AP39: 90 | AQ39: 200 | AR39: 150 | AS39: 150 | AT39: 170 | AU39: 140 | AV39: 130 | AW39: 150 | AX39: 210 | AZ39: =PERCENTILE(AO39:AX39,0.9) -> 201
B40: REAL | C40: 6.133 | D40: 6.249 | E40: 6.237 | F40: 6.195 | G40: 6.249 | H40: 6.109 | I40: 6.23 | J40: 6.191 | K40: 6.214 | L40: 6.228 | N40: =PERCENTILE(C40:L40,0.9) -> 6.249 | O40: =N8/N40 -> 5.1096655 | P40: =O40/8 -> 0.63870819 | U40: REAL | V40: 28.296 | W40: 26.964 | X40: 27.966 | Y40: 54.898 | Z40: 68.488 | AA40: 27.787 | AB40: 28.103 | AC40: 28.927 | AD40: 28.39 | AE40: 27.781 | AG40: =PERCENTILE(V40:AE40,0.9) -> 56.257 | AH40: =N8/AG40 -> 0.56757915 | AI40: =AH40/8 -> 0.070947393 | AN40: REAL | AO40: 39.588 | AP40: 24.545 | AQ40: 25.421 | AR40: 40.786 | AS40: 38.557 | AT40: 40.568 | AU40: 36.275 | AV40: 30.548 | AW40: 32.82 | AX40: 27.403 | AZ40: =PERCENTILE(AO40:AX40,0.9) -> 40.5898 | BA40: =N8/AZ40 -> 0.78665822 | BB40: =BA40/8 -> 0.098332278
A41: msdoor.mtx | B41: CPU | C41: 100 | D41: 100 | E41: 100 | F41: 90 | G41: 90 | H41: 100 | I41: 90 | J41: 110 | K41: 100 | L41: 100 | N41: =PERCENTILE(C41:L41,0.9) -> 101 | T41: msdoor.mtx | U41: CPU | V41: 590 | W41: 580 | X41: 580 | Y41: 570 | Z41: 560 | AA41: 560 | AB41: 600 | AC41: 580 | AD41: 610 | AE41: 580 | AG41: =PERCENTILE(V41:AE41,0.9) -> 601 | AM41: msdoor.mtx | AN41: CPU | AO41: 260 | AP41: 270 | AQ41: 280 | AR41: 220 | AS41: 310 | AT41: 440 | AU41: 220 | AV41: 270 | AW41: 230 | AX41: 570 | AZ41: =PERCENTILE(AO41:AX41,0.9) -> 453
B42: REAL | C42: 12.399 | D42: 12.105 | E42: 12.109 | F42: 12.124 | G42: 12.162 | H42: 12.321 | I42: 12.083 | J42: 12.107 | K42: 12.079 | L42: 12.116 | N42: =PERCENTILE(C42:L42,0.9) -> 12.3288 | O42: =N10/N42 -> 5.2291139 | P42: =O42/8 -> 0.65363924 | U42: REAL | V42: 74.059 | W42: 73.035 | X42: 72.112 | Y42: 96.733 | Z42: 71.057 | AA42: 70.799 | AB42: 75.101 | AC42: 73.002 | AD42: 75.848 | AE42: 72.082 | AG42: =PERCENTILE(V42:AE42,0.9) -> 77.9365 | AH42: =N10/AG42 -> 0.82719522 | AI42: =AH42/8 -> 0.1033994 | AN42: REAL | AO42: 67.251 | AP42: 63.333 | AQ42: 66.852 | AR42: 56.028 | AS42: 76.006 | AT42: 100.218 | AU42: 59.359 | AV42: 60.697 | AW42: 57.887 | AX42: 70.837 | AZ42: =PERCENTILE(AO42:AX42,0.9) -> 78.4272 | BA42: =N10/AZ42 -> 0.82201966 | BB42: =BA42/8 -> 0.10275246
A43: nlpkkt240.mtx | B43: CPU | C43: 3660 | D43: 2820 | E43: 2830 | F43: 2850 | G43: 2840 | H43: 3630 | I43: 2830 | J43: 2820 | K43: 2830 | L43: 3190 | N43: =PERCENTILE(C43:L43,0.9) -> 3633 | T43: nlpkkt240.mtx | U43: CPU | V43: 40800 | W43: 33860 | X43: 44860 | Y43: 30340 | Z43: 35280 | AA43: 35350 | AB43: 35270 | AC43: 35730 | AD43: 35690 | AE43: 34420 | AG43: =PERCENTILE(V43:AE43,0.9) -> 41206 | AM43: nlpkkt240.mtx | AN43: CPU | AO43: 28110 | AP43: 17730 | AQ43: 27280 | AR43: 23450 | AS43: 24800 | AT43: 23060 | AU43: 29400 | AV43: 20650 | AW43: 94260 | AX43: 55600 | AZ43: =PERCENTILE(AO43:AX43,0.9) -> 59466
B44: REAL | C44: 466.598 | D44: 391.003 | E44: 390.656 | F44: 391.992 | G44: 392.102 | H44: 461.876 | I44: 391.163 | J44: 391.264 | K44: 391.172 | L44: 439.941 | N44: =PERCENTILE(C44:L44,0.9) -> 462.3482 | O44: =N12/N44 -> 3.9984163 | P44: =O44/8 -> 0.49980204 | U44: REAL | V44: 5233.24 | W44: 4252.426 | X44: 6510.184 | Y44: 3910.162 | Z44: 4420.59 | AA44: 4440.839 | AB44: 4430.698 | AC44: 4488.114 | AD44: 4480.684 | AE44: 4322.436 | AG44: =PERCENTILE(V44:AE44,0.9) -> 5360.9344 | AH44: =N12/AG44 -> 0.34483925 | AI44: =AH44/8 -> 0.043104906 | AN44: REAL | AO44: 3549.218 | AP44: 2367.393 | AQ44: 3696.341 | AR44: 3029.196 | AS44: 3183.944 | AT44: 3099.597 | AU44: 4079.037 | AV44: 2754.894 | AW44: 12574.075 | AX44: 7220.296 | AZ44: =PERCENTILE(AO44:AX44,0.9) -> 7755.6739 | BA44: =N12/AZ44 -> 0.23836234 | BB44: =BA44/8 -> 0.029795293
A48: STATIC – 16 | T48: DYNAMIC – 16 | AM48: GUIDED – 16
A49: matrice | B49: metrica | C49: Test 1 | D49: Test 2 | E49: Test 3 | F49: Test 4 | G49: Test 5 | H49: Test 6 | I49: Test 7 | J49: Test 8 | K49: Test 9 | L49: Test 10 | N49: 90 percentile | O49: Speedup | P49: Efficiency | T49: matrice | U49: metrica | V49: Test 1 | W49: Test 2 | X49: Test 3 | Y49: Test 4 | Z49: Test 5 | AA49: Test 6 | AB49: Test 7 | AC49: Test 8 | AD49: Test 9 | AE49: Test 10 | AG49: 90 percentile | AH49: Speedup | AI49: Efficiency | AM49: matrice | AN49: metrica | AO49: Test 1 | AP49: Test 2 | AQ49: Test 3 | AR49: Test 4 | AS49: Test 5 | AT49: Test 6 | AU49: Test 7 | AV49: Test 8 | AW49: Test 9 | AX49: Test 10 | AZ49: 90 percentile | BA49: Speedup | BB49: Efficiency
A50: ML_Geer.mtx | B50: CPU | C50: 880 | D50: 740 | E50: 870 | F50: 780 | G50: 890 | H50: 880 | I50: 830 | J50: 930 | K50: 890 | L50: 930 | N50: =PERCENTILE(C50:L50,0.9) -> 930 | T50: ML_Geer.mtx | U50: CPU | V50: 3240 | W50: 3250 | X50: 3280 | Y50: 3210 | Z50: 3350 | AA50: 3270 | AB50: 3260 | AC50: 3350 | AD50: 3240 | AE50: 3270 | AG50: =PERCENTILE(V50:AE50,0.9) -> 3350 | AM50: ML_Geer.mtx | AN50: CPU | AO50: 2910 | AP50: 3110 | AQ50: 3090 | AR50: 3150 | AS50: 3100 | AT50: 3100 | AU50: 3120 | AV50: 3140 | AW50: 2870 | AX50: 3050 | AZ50: =PERCENTILE(AO50:AX50,0.9) -> 3141
...

Sheet speedup_tables
A1: ML_Geer
A2: Number of threads | B2: Static | C2: Dynamic (default) | D2: Guided (default) | E2: Dynamic (100) | F2: Guided (100)
A3: 4 | B3: =INDEX(overall!O$21:O$1000, 1 + (ROWS($B$3:B3)-1)*15) -> 2.7452407 | C3: =INDEX(overall!AH$21:AH$1000, 1 + (ROWS($C$3:C3)-1)*15) -> 0.90012087 | D3: =INDEX(overall!BA$21:BA$1000, 1 + (ROWS($D$3:D3)-1)*15) -> 0.77380614 | E3: =INDEX(overall!AH$98:AH$1000, 1 + (ROWS($E$3:E3)-1)*15) -> 7.7580778 | F3: =INDEX(overall!BA$98:BA$1000, 1 + (ROWS($F$3:F3)-1)*15) -> 3.3391232
A4: 8 | B4: =INDEX(overall!O$21:O$1000, 1 + (ROWS($B$3:B4)-1)*15) -> 5.360612 | C4: =INDEX(overall!AH$21:AH$1000, 1 + (ROWS($C$3:C4)-1)*15) -> 1.0945116 | D4: =INDEX(overall!BA$21:BA$1000, 1 + (ROWS($D$3:D4)-1)*15) -> 0.89289007 | E4: =INDEX(overall!AH$98:AH$1000, 1 + (ROWS($E$3:E4)-1)*15) -> 2.1274599 | F4: =INDEX(overall!BA$98:BA$1000, 1 + (ROWS($F$3:F4)-1)*15) -> 1.2499812
A5: 16 | B5: =INDEX(overall!O$21:O$1000, 1 + (ROWS($B$3:B5)-1)*15) -> 5.0680127 | C5: =INDEX(overall!AH$21:AH$1000, 1 + (ROWS($C$3:C5)-1)*15) -> 1.5747553 | D5: =INDEX(overall!BA$21:BA$1000, 1 + (ROWS($D$3:D5)-1)*15) -> 1.7016307 | E5: =INDEX(overall!AH$98:AH$1000, 1 + (ROWS($E$3:E5)-1)*15) -> 0.83926195 | F5: =INDEX(overall!BA$98:BA$1000, 1 + (ROWS($F$3:F5)-1)*15) -> 5.3653142
A6: 32 | B6: =INDEX(overall!O$21:O$1000, 1 + (ROWS($B$3:B6)-1)*15) -> 8.9100242 | C6: =INDEX(overall!AH$21:AH$1000, 1 + (ROWS($C$3:C6)-1)*15) -> 0.8969563 | D6: =INDEX(overall!BA$21:BA$1000, 1 + (ROWS($D$3:D6)-1)*15) -> 2.5579859 | E6: =INDEX(overall!AH$98:AH$1000, 1 + (ROWS($E$3:E6)-1)*15) -> 10.635936 | F6: =INDEX(overall!BA$98:BA$1000, 1 + (ROWS($F$3:F6)-1)*15) -> 4.8061915
A7: 64 | B7: =INDEX(overall!O$21:O$1000, 1 + (ROWS($B$3:B7)-1)*15) -> 3.6246848 | C7: =INDEX(overall!AH$21:AH$1000, 1 + (ROWS($C$3:C7)-1)*15) -> 2.5522245 | D7: =INDEX(overall!BA$21:BA$1000, 1 + (ROWS($D$3:D7)-1)*15) -> 1.4706058 | E7: =INDEX(overall!AH$98:AH$1000, 1 + (ROWS($E$3:E7)-1)*15) -> 1.0390297 | F7: =INDEX(overall!BA$98:BA$1000, 1 + (ROWS($F$3:F7)-1)*15) -> 6.7772709
A13: Pflow_742
A14: Number of threads | B14: Static | C14: Dynamic (default) | D14: Guided (default) | E14: Dynamic (100) | F14: Guided (100)
A15: 4 | B15: =INDEX(overall!O$23:O$1000, 1 + (ROWS($B$15:B15)-1)*15) -> 5.4216873 | C15: =INDEX(overall!AH$23:AH$1000, 1 + (ROWS($C$15:C15)-1)*15) -> 0.55668888 | D15: =INDEX(overall!BA$23:BA$1000, 1 + (ROWS($D$15:D15)-1)*15) -> 0.78957888 | E15: =INDEX(overall!AH$100:AH$1000, 1 + (ROWS($E$15:E15)-1)*15) -> 6.7732755 | F15: =INDEX(overall!BA$100:BA$1000, 1 + (ROWS($F$15:F15)-1)*15) -> 6.7784762
A16: 8 | B16: =INDEX(overall!O$23:O$1000, 1 + (ROWS($B$15:B16)-1)*15) -> 4.644122 | C16: =INDEX(overall!AH$23:AH$1000, 1 + (ROWS($C$15:C16)-1)*15) -> 0.49291891 | D16: =INDEX(overall!BA$23:BA$1000, 1 + (ROWS($D$15:D16)-1)*15) -> 0.799578 | E16: =INDEX(overall!AH$100:AH$1000, 1 + (ROWS($E$15:E16)-1)*15) -> 3.184996 | F16: =INDEX(overall!BA$100:BA$1000, 1 + (ROWS($F$15:F16)-1)*15) -> 6.1066605
A17: 16 | B17: =INDEX(overall!O$23:O$1000, 1 + (ROWS($B$15:B17)-1)*15) -> 4.2465055 | C17: =INDEX(overall!AH$23:AH$1000, 1 + (ROWS($C$15:C17)-1)*15) -> 1.058894 | D17: =INDEX(overall!BA$23:BA$1000, 1 + (ROWS($D$15:D17)-1)*15) -> 0.79060298 | E17: =INDEX(overall!AH$100:AH$1000, 1 + (ROWS($E$15:E17)-1)*15) -> 1.6838077 | F17: =INDEX(overall!BA$100:BA$1000, 1 + (ROWS($F$15:F17)-1)*15) -> 5.767133
A18: 32 | B18: =INDEX(overall!O$23:O$1000, 1 + (ROWS($B$15:B18)-1)*15) -> 7.9543306 | C18: =INDEX(overall!AH$23:AH$1000, 1 + (ROWS($C$15:C18)-1)*15) -> 0.91852736 | D18: =INDEX(overall!BA$23:BA$1000, 1 + (ROWS($D$15:D18)-1)*15) -> 1.6248639 | E18: =INDEX(overall!AH$100:AH$1000, 1 + (ROWS($E$15:E18)-1)*15) -> 9.7658479 | F18: =INDEX(overall!BA$100:BA$1000, 1 + (ROWS($F$15:F18)-1)*15) -> 4.9204024
A19: 64 | B19: =INDEX(overall!O$23:O$1000, 1 + (ROWS($B$15:B19)-1)*15) -> 2.6353053 | C19: =INDEX(overall!AH$23:AH$1000, 1 + (ROWS($C$15:C19)-1)*15) -> 1.3968459 | D19: =INDEX(overall!BA$23:BA$1000, 1 + (ROWS($D$15:D19)-1)*15) -> 0.28973828 | E19: =INDEX(overall!AH$100:AH$1000, 1 + (ROWS($E$15:E19)-1)*15) -> 0.93418437 | F19: =INDEX(overall!BA$100:BA$1000, 1 + (ROWS($F$15:F19)-1)*15) -> 3.9206294
A25: bmwcra_1
A26: Number of threads | B26: Static | C26: Dynamic (default) | D26: Guided (default) | E26: Dynamic (100) | F26: Guided (100)
A27: 4 | B27: =INDEX(overall!O$25:O$1000, 1 + (ROWS($B$27:B27)-1)*15) -> 0.7194377 | C27: =INDEX(overall!AH$25:AH$1000, 1 + (ROWS($C$27:C27)-1)*15) -> 0.85930003 | D27: =INDEX(overall!BA$25:BA$1000, 1 + (ROWS($D$27:D27)-1)*15) -> 0.91759537 | E27: =INDEX(overall!AH$102:AH$1000, 1 + (ROWS($E$27:E27)-1)*15) -> 3.374119 | F27: =INDEX(overall!BA$102:BA$1000, 1 + (ROWS($F$27:F27)-1)*15) -> 0.88623394
A28: 8 | B28: =INDEX(overall!O$25:O$1000, 1 + (ROWS($B$27:B28)-1)*15) -> 5.1096655 | C28: =INDEX(overall!AH$25:AH$1000, 1 + (ROWS($C$27:C28)-1)*15) -> 0.56757915 | D28: =INDEX(overall!BA$25:BA$1000, 1 + (ROWS($D$27:D28)-1)*15) -> 0.78665822 | E28: =INDEX(overall!AH$102:AH$1000, 1 + (ROWS($E$27:E28)-1)*15) -> 1.3995065 | F28: =INDEX(overall!BA$102:BA$1000, 1 + (ROWS($F$27:F28)-1)*15) -> 1.7959458
A29: 16 | B29: =INDEX(overall!O$25:O$1000, 1 + (ROWS($B$27:B29)-1)*15) -> 4.5313702 | C29: =INDEX(overall!AH$25:AH$1000, 1 + (ROWS($C$27:C29)-1)*15) -> 0.22936209 | D29: =INDEX(overall!BA$25:BA$1000, 1 + (ROWS($D$27:D29)-1)*15) -> 1.5677161 | E29: =INDEX(overall!AH$102:AH$1000, 1 + (ROWS($E$27:E29)-1)*15) -> 9.2540865 | F29: =INDEX(overall!BA$102:BA$1000, 1 + (ROWS($F$27:F29)-1)*15) -> 5.5227446
A30: 32 | B30: =INDEX(overall!O$25:O$1000, 1 + (ROWS($B$27:B30)-1)*15) -> 6.8605346 | C30: =INDEX(overall!AH$25:AH$1000, 1 + (ROWS($C$27:C30)-1)*15) -> 0.78173743 | D30: =INDEX(overall!BA$25:BA$1000, 1 + (ROWS($D$27:D30)-1)*15) -> 1.1492251 | E30: =INDEX(overall!AH$102:AH$1000, 1 + (ROWS($E$27:E30)-1)*15) -> 7.6039007 | F30: =INDEX(overall!BA$102:BA$1000, 1 + (ROWS($F$27:F30)-1)*15) -> 4.5565243
A31: 64 | B31: =INDEX(overall!O$25:O$1000, 1 + (ROWS($B$27:B31)-1)*15) -> 1.1187716 | C31: =INDEX(overall!AH$25:AH$1000, 1 + (ROWS($C$27:C31)-1)*15) -> 1.0959016 | D31: =INDEX(overall!BA$25:BA$1000, 1 + (ROWS($D$27:D31)-1)*15) -> 0.28027056 | E31: =INDEX(overall!AH$102:AH$1000, 1 + (ROWS($E$27:E31)-1)*15) -> 0.38284951 | F31: =INDEX(overall!BA$102:BA$1000, 1 + (ROWS($F$27:F31)-1)*15) -> 1.1111216
A37: msdoor
A38: Number of threads | B38: Static | C38: Dynamic (default) | D38: Guided (default) | E38: Dynamic (100) | F38: Guided (100)
A39: 4 | B39: =INDEX(overall!O$27:O$1000, 1 + (ROWS($B$39:B39)-1)*15) -> 6.3675935 | C39: =INDEX(overall!AH$27:AH$1000, 1 + (ROWS($C$39:C39)-1)*15) -> 0.36718652 | D39: =INDEX(overall!BA$27:BA$1000, 1 + (ROWS($D$39:D39)-1)*15) -> 0.85555585 | E39: =INDEX(overall!AH$104:AH$1000, 1 + (ROWS($E$39:E39)-1)*15) -> 6.9082736 | F39: =INDEX(overall!BA$104:BA$1000, 1 + (ROWS($F$39:F39)-1)*15) -> 7.3689462
A40: 8 | B40: =INDEX(overall!O$27:O$1000, 1 + (ROWS($B$39:B40)-1)*15) -> 5.2291139 | C40: =INDEX(overall!AH$27:AH$1000, 1 + (ROWS($C$39:C40)-1)*15) -> 0.82719522 | D40: =INDEX(overall!BA$27:BA$1000, 1 + (ROWS($D$39:D40)-1)*15) -> 0.82201966 | E40: =INDEX(overall!AH$104:AH$1000, 1 + (ROWS($E$39:E40)-1)*15) -> 9.8487145 | F40: =INDEX(overall!BA$104:BA$1000, 1 + (ROWS($F$39:F40)-1)*15) -> 11.43711
A41: 16 | B41: =INDEX(overall!O$27:O$1000, 1 + (ROWS($B$39:B41)-1)*15) -> 4.7916088 | C41: =INDEX(overall!AH$27:AH$1000, 1 + (ROWS($C$39:C41)-1)*15) -> 1.1089691 | D41: =INDEX(overall!BA$27:BA$1000, 1 + (ROWS($D$39:D41)-1)*15) -> 1.2241047 | E41: =INDEX(overall!AH$104:AH$1000, 1 + (ROWS($E$39:E41)-1)*15) -> 10.509031 | F41: =INDEX(overall!BA$104:BA$1000, 1 + (ROWS($F$39:F41)-1)*15) -> 2.5249662
A42: 32 | B42: =INDEX(overall!O$27:O$1000, 1 + (ROWS($B$39:B42)-1)*15) -> 8.385736 | C42: =INDEX(overall!AH$27:AH$1000, 1 + (ROWS($C$39:C42)-1)*15) -> 0.93245597 | D42: =INDEX(overall!BA$27:BA$1000, 1 + (ROWS($D$39:D42)-1)*15) -> 1.7874656 | E42: =INDEX(overall!AH$104:AH$1000, 1 + (ROWS($E$39:E42)-1)*15) -> 10.140893 | F42: =INDEX(overall!BA$104:BA$1000, 1 + (ROWS($F$39:F42)-1)*15) -> 4.6380026
A43: 64 | B43: =INDEX(overall!O$27:O$1000, 1 + (ROWS($B$39:B43)-1)*15) -> 1.7759385 | C43: =INDEX(overall!AH$27:AH$1000, 1 + (ROWS($C$39:C43)-1)*15) -> 1.4341771 | D43: =INDEX(overall!BA$27:BA$1000, 1 + (ROWS($D$39:D43)-1)*15) -> 0.30802599 | E43: =INDEX(overall!AH$104:AH$1000, 1 + (ROWS($E$39:E43)-1)*15) -> 0.55320893 | F43: =INDEX(overall!BA$104:BA$1000, 1 + (ROWS($F$39:F43)-1)*15) -> 2.8644735
A49: nlpkkt240
A50: Number of threads | B50: Static | C50: Dynamic (default) | D50: Guided (default) | E50: Dynamic (100) | F50: Guided (100)
A51: 4 | B51: =INDEX(overall!O$29:O$1000, 1 + (ROWS($B$51:B51)-1)*15) -> 0.71233194 | C51: =INDEX(overall!AH$29:AH$1000, 1 + (ROWS($C$51:C51)-1)*15) -> 0.10572146 | D51: =INDEX(overall!BA$29:BA$1000, 1 + (ROWS($D$51:D51)-1)*15) -> 0.14556276 | E51: =INDEX(overall!AH$106:AH$1000, 1 + (ROWS($E$51:E51)-1)*15) -> 5.1477704 | F51: =INDEX(overall!BA$106:BA$1000, 1 + (ROWS($F$51:F51)-1)*15) -> 0.73266618
A52: 8 | B52: =INDEX(overall!O$29:O$1000, 1 + (ROWS($B$51:B52)-1)*15) -> 3.9984163 | C52: =INDEX(overall!AH$29:AH$1000, 1 + (ROWS($C$51:C52)-1)*15) -> 0.34483925 | D52: =INDEX(overall!BA$29:BA$1000, 1 + (ROWS($D$51:D52)-1)*15) -> 0.23836234 | E52: =INDEX(overall!AH$106:AH$1000, 1 + (ROWS($E$51:E52)-1)*15) -> 1.4955875 | F52: =INDEX(overall!BA$106:BA$1000, 1 + (ROWS($F$51:F52)-1)*15) -> 0.83530239
A53: 16 | B53: =INDEX(overall!O$29:O$1000, 1 + (ROWS($B$51:B53)-1)*15) -> 3.8882114 | C53: =INDEX(overall!AH$29:AH$1000, 1 + (ROWS($C$51:C53)-1)*15) -> 0.5223886 | D53: =INDEX(overall!BA$29:BA$1000, 1 + (ROWS($D$51:D53)-1)*15) -> 0.13699681 | E53: =INDEX(overall!AH$106:AH$1000, 1 + (ROWS($E$51:E53)-1)*15) -> 0.3539452 | F53: =INDEX(overall!BA$106:BA$1000, 1 + (ROWS($F$51:F53)-1)*15) -> 2.1084234
A54: 32 | B54: =INDEX(overall!O$29:O$1000, 1 + (ROWS($B$51:B54)-1)*15) -> 6.5022845 | C54: =INDEX(overall!AH$29:AH$1000, 1 + (ROWS($C$51:C54)-1)*15) -> 0.13830942 | D54: =INDEX(overall!BA$29:BA$1000, 1 + (ROWS($D$51:D54)-1)*15) -> 0.79029804 | E54: =INDEX(overall!AH$106:AH$1000, 1 + (ROWS($E$51:E54)-1)*15) -> 8.3809836 | F54: =INDEX(overall!BA$106:BA$1000, 1 + (ROWS($F$51:F54)-1)*15) -> 4.2769705
A55: 64 | B55: =INDEX(overall!O$29:O$1000, 1 + (ROWS($B$51:B55)-1)*15) -> 3.253613 | C55: =INDEX(overall!AH$29:AH$1000, 1 + (ROWS($C$51:C55)-1)*15) -> 0.87786687 | D55: =INDEX(overall!BA$29:BA$1000, 1 + (ROWS($D$51:D55)-1)*15) -> 0.049853437 | E55: =INDEX(overall!AH$106:AH$1000, 1 + (ROWS($E$51:E55)-1)*15) -> 0.20605012 | F55: =INDEX(overall!BA$106:BA$1000, 1 + (ROWS($F$51:F55)-1)*15) -> 7.8515859
